Workbook
Name DESCRIPTORS: 'Helper (Do Not Delete)'!$T$3:$W$7
Name FemaleLearners: INPUT!$B$63:$B$112
Name MaleLearners: INPUT!$B$12:$B$61
Name NewTransmu: 'Helper (Do Not Delete)'!$H$3:$K$43
Name T1_Names: TERM1!$B$12:$B$112
Name TRANSMUTATION_TABLE: 'DO NOT DELETE'!$G$2:$J$42

Sheet INPUT
A1: Class Record
A3: (Waiting for the Official DepEd Order)
B4: REGION | G4: Region IV-A (CALABARZON) | I4: DIVISION | L4: Schools Division of Quezon
B5: SCHOOL NAME | G5: Atimonan Central School Annex | Q5: SCHOOL ID | S5: 108511 | V5: SCHOOL YEAR | Y5: 2025-2026
F7: GRADE & SECTION: | J7: Grade 6 - Rizal | N7: TEACHER: | Q7: Jose Miguel Reyes | W7: SUBJECT: | Y7: Araling Panlipunan
B8: LEARNERS' NAMES
B10: HIGHEST POSSIBLE SCORE
B11: MALE
A12: 1 | B12: Aguilar, Adrian | AS12: =(V12/$V$10)*100 -> #DIV/0!
A13: 2 | B13: Alcantara, Angelo | AS13: =(V13/$V$10)*100 -> #DIV/0!
A14: 3 | B14: Andrada, Anton | AS14: =(V14/$V$10)*100 -> #DIV/0!
A15: 4 | B15: Bautista, Bryan | AS15: =(V15/$V$10)*100 -> #DIV/0!
A16: 5 | B16: Bernardo, Caleb | AS16: =(V16/$V$10)*100 -> #DIV/0!
A17: 6 | B17: Castillo, Carlo | AS17: =(V17/$V$10)*100 -> #DIV/0!
A18: 7 | B18: Cruz, Christian | AS18: =(V18/$V$10)*100 -> #DIV/0!
A19: 8 | B19: Dela Cruz, Daniel | AS19: =(V19/$V$10)*100 -> #DIV/0!
A20: 9 | B20: Diaz, Darren | AS20: =(V20/$V$10)*100 -> #DIV/0!
A21: 10 | B21: Evangelista, Diego | AS21: =(V21/$V$10)*100 -> #DIV/0!
A22: 11 | B22: Fernandez, Ethan | AS22: =(V22/$V$10)*100 -> #DIV/0!
A23: 12 | B23: Garcia, Gabriel | AS23: =(V23/$V$10)*100 -> #DIV/0!
... A61: 50 | B61: Escobar, Gian | AS61: =(V61/$V$10)*100 -> #DIV/0!
B62: FEMALE | AS62: =(V62/$V$10)*100 -> #DIV/0!
A63: 1 | B63: Fernandez, Alyssa | AS63: =(V63/$V$10)*100 -> #DIV/0!
A64: 2 | B64: Garcia, Angela | AS64: =(V64/$V$10)*100 -> #DIV/0!
A65: 3 | B65: Gonzales, Bea | AS65: =(V65/$V$10)*100 -> #DIV/0!
A66: 4 | B66: Hernandez, Bianca | AS66: =(V66/$V$10)*100 -> #DIV/0!
A67: 5 | B67: Ilagan, Camille | AS67: =(V67/$V$10)*100 -> #DIV/0!
A68: 6 | B68: Jimenez, Carla | AS68: =(V68/$V$10)*100 -> #DIV/0!
A69: 7 | B69: Lacson, Chloe | AS69: =(V69/$V$10)*100 -> #DIV/0!
A70: 8 | B70: Lim, Clarisse | AS70: =(V70/$V$10)*100 -> #DIV/0!
A71: 9 | B71: Manalo, Danica | AS71: =(V71/$V$10)*100 -> #DIV/0!
A72: 10 | B72: Mendoza, Diana | AS72: =(V72/$V$10)*100 -> #DIV/0!
A73: 11 | B73: Navarro, Elena | AS73: =(V73/$V$10)*100 -> #DIV/0!
A74: 12 | B74: Ocampo, Ella | AS74: =(V74/$V$10)*100 -> #DIV/0!
... A112: 50 | B112: Evangelista, Danielle | AS112: =(V112/$V$10)*100 -> #DIV/0!

Sheet TERM1
A1: Class Record
B4: REGION | G4: =INPUT!G4 -> Region IV-A (CALABARZON) | I4: DIVISION | L4: =INPUT!L4 -> Schools Division of Quezon
B5: SCHOOL NAME | G5: =INPUT!G5 -> Atimonan Central School Annex | Q5: SCHOOL ID | S5: =INPUT!S5 -> 108511 | V5: SCHOOL YEAR | Z5: =INPUT!Y5 -> 2025-2026
A7: TERM 1 | F7: GRADE & SECTION: | J7: =INPUT!J7 -> Grade 6 - Rizal | N7: TEACHER: | Q7: =INPUT!Q7 -> Jose Miguel Reyes | X7: SUBJECT: | Z7: =INPUT!Y7 -> Araling Panlipunan
B8: LEARNERS' NAMES | F8: WRITTEN / ORAL WORKS (20%) | N8: PRODUCT / PERFORMANCE TASKS (50%) | T8: SUMMATIVE TESTS AND TERM EXAMINATIONS (30%) | Z8: Initial Grade | AA8: TERM GRADE | AB8: DESCRIPTOR
F9: 1 | G9: 2 | H9: 3 | I9: 4 | J9: 5 | K9: Total | L9: PS | M9: WS | N9: 1 | O9: 2 | P9: 3 | Q9: Total | R9: PS | S9: WS | T9: ST1 | U9: ST2 | V9: TE | W9: Total | X9: PS | Y9: WS
B10: HIGHEST POSSIBLE SCORE | F10: 20 | G10: 20 | H10: 20 | I10: 20 | J10: 20 | K10: =IF(COUNT($F10:$J10)=0,"",SUM($F10:$J10)) -> 100 | L10: 100 | M10: 0.2 | N10: 50 | O10: 50 | P10: 50 | Q10: =IF(COUNT($N10:$P10)=0,"",SUM($N10:$P10)) -> 150 | R10: 100 | S10: 0.5 | T10: 40 | U10: 40 | V10: 40 | W10: {=IF(COUNT($T10:$V10=0),"",SUM($T10:$V10))} -> 120 | X10: 100 | Y10: 0.3
B11: MALE | AD11: TEST/EXAM RESULT ANALYSIS | AV11: ST1 | AW11: ST2 | AX11: TE
A12: 1 | B12: =INPUT!B12 -> Aguilar, Adrian | F12: 19 | G12: 18 | H12: 19 | I12: 20 | J12: 20 | K12: =IF(COUNT($F12:$J12)=0,"",SUM($F12:$J12)) -> 96 | L12: =IF(ISERROR(IF($K12="","",ROUND(($K12/$K$10)*$L$10,2))),"",IF($K12="","",ROUND(($K12/$K$10)*$L$10,2))) -> 96 | M12: =IF($L12="","",ROUND($L12*$M$10,2)) -> 19.2 | N12: 50 | O12: 50 | P12: 46 | Q12: =IF(COUNT($N12:$P12)=0,"",SUM($N12:$P12)) -> 146 | R12: =IF(ISERROR(IF($Q12="","",ROUND(($Q12/$Q$10)*$R$10,2))),"",IF($Q12="","",ROUND(($Q12/$Q$10)*$R$10,2))) -> 97.33 | S12: =IF($R12="","",ROUND($R12*$S$10,2)) -> 48.67 | T12: 35 | U12: 38 | V12: 38 | W12: =IF(COUNT($T12:$V12)=0,"",SUM($T12:$V12)) -> 111 | X12: =IF(ISERROR(IF($W12="","",ROUND(($W12/$W$10)*$X$10,2))),"",IF($W12="","",ROUND(($W12/$W$10)*$X$10,2))) -> 92.5 | Y12: =IF($X12="","",ROUND($X12*$Y$10,2)) -> 27.75 | Z12: =IF(ISERROR(IF($W12="","",ROUND(SUM($M12,$S12,$Y12),2))),"",IF($W12="","",ROUND(SUM($M12,$S12,$Y12),2))) -> 95.62 | AA12: =IF(ISERROR(IF($W12="","",VLOOKUP(Z12,NewTransmu,4,TRUE))),"",IF($W12="","",VLOOKUP(Z12,NewTransmu,4,TRUE))) -> 97 | AB12: =IF(ISERROR(IF(AA12="","",VLOOKUP(AA12,DESCRIPTORS,4,TRUE))),"",IF(AA12="","",VLOOKUP(AA12,DESCRIPTORS,4,TRUE))) -> Advancing | AV12: =(T12/$T$10)*100 -> 87.5 | AW12: =(U12/$U$10)*100 -> 95 | AX12: =(V12/$V$10)*100 -> 95
A13: 2 | B13: =INPUT!B13 -> Alcantara, Angelo | F13: 19 | G13: 19 | H13: 20 | I13: 19 | J13: 19 | K13: =IF(COUNT($F13:$J13)=0,"",SUM($F13:$J13)) -> 96 | L13: =IF(ISERROR(IF($K13="","",ROUND(($K13/$K$10)*$L$10,2))),"",IF($K13="","",ROUND(($K13/$K$10)*$L$10,2))) -> 96 | M13: =IF($L13="","",ROUND($L13*$M$10,2)) -> 19.2 | N13: 49 | O13: 50 | P13: 48 | Q13: =IF(COUNT($N13:$P13)=0,"",SUM($N13:$P13)) -> 147 | R13: =IF(ISERROR(IF($Q13="","",ROUND(($Q13/$Q$10)*$R$10,2))),"",IF($Q13="","",ROUND(($Q13/$Q$10)*$R$10,2))) -> 98 | S13: =IF($R13="","",ROUND($R13*$S$10,2)) -> 49 | T13: 35 | U13: 36 | V13: 38 | W13: =IF(COUNT($T13:$V13)=0,"",SUM($T13:$V13)) -> 109 | X13: =IF(ISERROR(IF($W13="","",ROUND(($W13/$W$10)*$X$10,2))),"",IF($W13="","",ROUND(($W13/$W$10)*$X$10,2))) -> 90.83 | Y13: =IF($X13="","",ROUND($X13*$Y$10,2)) -> 27.25 | Z13: =IF(ISERROR(IF($V13="","",ROUND(SUM($M13,$S13,$Y13),2))),"",IF($V13="","",ROUND(SUM($M13,$S13,$Y13),2))) -> 95.45 | AA13: =IF(ISERROR(IF($V13="","",VLOOKUP(Z13,NewTransmu,4,TRUE))),"",IF($V13="","",VLOOKUP(Z13,NewTransmu,4,TRUE))) -> 97 | AB13: =IF(ISERROR(IF(AA13="","",VLOOKUP(AA13,DESCRIPTORS,4,TRUE))),"",IF(AA13="","",VLOOKUP(AA13,DESCRIPTORS,4,TRUE))) -> Advancing | AE13: ST1 | AF13: ST2 | AG13: TE | AV13: =(T13/$T$10)*100 -> 87.5 | AW13: =(U13/$U$10)*100 -> 90 | AX13: =(V13/$V$10)*100 -> 95
A14: 3 | B14: =INPUT!B14 -> Andrada, Anton | F14: 15 | G14: 14 | H14: 16 | I14: 17 | J14: 16 | K14: =IF(COUNT($F14:$J14)=0,"",SUM($F14:$J14)) -> 78 | L14: =IF(ISERROR(IF($K14="","",ROUND(($K14/$K$10)*$L$10,2))),"",IF($K14="","",ROUND(($K14/$K$10)*$L$10,2))) -> 78 | M14: =IF($L14="","",ROUND($L14*$M$10,2)) -> 15.6 | N14: 41 | O14: 39 | P14: 41 | Q14: =IF(COUNT($N14:$P14)=0,"",SUM($N14:$P14)) -> 121 | R14: =IF(ISERROR(IF($Q14="","",ROUND(($Q14/$Q$10)*$R$10,2))),"",IF($Q14="","",ROUND(($Q14/$Q$10)*$R$10,2))) -> 80.67 | S14: =IF($R14="","",ROUND($R14*$S$10,2)) -> 40.34 | T14: 27 | U14: 30 | V14: 29 | W14: =IF(COUNT($T14:$V14)=0,"",SUM($T14:$V14)) -> 86 | X14: =IF(ISERROR(IF($W14="","",ROUND(($W14/$W$10)*$X$10,2))),"",IF($W14="","",ROUND(($W14/$W$10)*$X$10,2))) -> 71.67 | Y14: =IF($X14="","",ROUND($X14*$Y$10,2)) -> 21.5 | Z14: =IF(ISERROR(IF($V14="","",ROUND(SUM($M14,$S14,$Y14),2))),"",IF($V14="","",ROUND(SUM($M14,$S14,$Y14),2))) -> 77.44 | AA14: =IF(ISERROR(IF($V14="","",VLOOKUP(Z14,NewTransmu,4,TRUE))),"",IF($V14="","",VLOOKUP(Z14,NewTransmu,4,TRUE))) -> 79 | AB14: =IF(ISERROR(IF(AA14="","",VLOOKUP(AA14,DESCRIPTORS,4,TRUE))),"",IF(AA14="","",VLOOKUP(AA14,DESCRIPTORS,4,TRUE))) -> Connecting | AD14: Number of Examinees: | AE14: =COUNTA(T12:T112) -> 100 | AF14: =COUNTA(U12:U112) -> 100 | AG14: =COUNTA(V12:V112) -> 100 | AV14: =(T14/$T$10)*100 -> 67.5 | AW14: =(U14/$U$10)*100 -> 75 | AX14: =(V14/$V$10)*100 -> 72.5
A15: 4 | B15: =INPUT!B15 -> Bautista, Bryan | F15: 13 | G15: 14 | H15: 14 | I15: 15 | J15: 15 | K15: =IF(COUNT($F15:$J15)=0,"",SUM($F15:$J15)) -> 71 | L15: =IF(ISERROR(IF($K15="","",ROUND(($K15/$K$10)*$L$10,2))),"",IF($K15="","",ROUND(($K15/$K$10)*$L$10,2))) -> 71 | M15: =IF($L15="","",ROUND($L15*$M$10,2)) -> 14.2 | N15: 35 | O15: 37 | P15: 34 | Q15: =IF(COUNT($N15:$P15)=0,"",SUM($N15:$P15)) -> 106 | R15: =IF(ISERROR(IF($Q15="","",ROUND(($Q15/$Q$10)*$R$10,2))),"",IF($Q15="","",ROUND(($Q15/$Q$10)*$R$10,2))) -> 70.67 | S15: =IF($R15="","",ROUND($R15*$S$10,2)) -> 35.34 | T15: 27 | U15: 26 | V15: 27 | W15: =IF(COUNT($T15:$V15)=0,"",SUM($T15:$V15)) -> 80 | X15: =IF(ISERROR(IF($W15="","",ROUND(($W15/$W$10)*$X$10,2))),"",IF($W15="","",ROUND(($W15/$W$10)*$X$10,2))) -> 66.67 | Y15: =IF($X15="","",ROUND($X15*$Y$10,2)) -> 20 | Z15: =IF(ISERROR(IF($V15="","",ROUND(SUM($M15,$S15,$Y15),2))),"",IF($V15="","",ROUND(SUM($M15,$S15,$Y15),2))) -> 69.54 | AA15: =IF(ISERROR(IF($V15="","",VLOOKUP(Z15,NewTransmu,4,TRUE))),"",IF($V15="","",VLOOKUP(Z15,NewTransmu,4,TRUE))) -> 74 | AB15: =IF(ISERROR(IF(AA15="","",VLOOKUP(AA15,DESCRIPTORS,4,TRUE))),"",IF(AA15="","",VLOOKUP(AA15,DESCRIPTORS,4,TRUE))) -> Developing | AD15: Highest Possible Score: | AE15: =T10 -> 40 | AF15: =U10 -> 40 | AG15: =V10 -> 40 | AV15: =(T15/$T$10)*100 -> 67.5 | AW15: =(U15/$U$10)*100 -> 65 | AX15: =(V15/$V$10)*100 -> 67.5
A16: 5 | B16: =INPUT!B16 -> Bernardo, Caleb | F16: 19 | G16: 18 | H16: 20 | I16: 18 | J16: 19 | K16: =IF(COUNT($F16:$J16)=0,"",SUM($F16:$J16)) -> 94 | L16: =IF(ISERROR(IF($K16="","",ROUND(($K16/$K$10)*$L$10,2))),"",IF($K16="","",ROUND(($K16/$K$10)*$L$10,2))) -> 94 | M16: =IF($L16="","",ROUND($L16*$M$10,2)) -> 18.8 | N16: 49 | O16: 48 | P16: 50 | Q16: =IF(COUNT($N16:$P16)=0,"",SUM($N16:$P16)) -> 147 | R16: =IF(ISERROR(IF($Q16="","",ROUND(($Q16/$Q$10)*$R$10,2))),"",IF($Q16="","",ROUND(($Q16/$Q$10)*$R$10,2))) -> 98 | S16: =IF($R16="","",ROUND($R16*$S$10,2)) -> 49 | T16: 38 | U16: 34 | V16: 33 | W16: =IF(COUNT($T16:$V16)=0,"",SUM($T16:$V16)) -> 105 | X16: =IF(ISERROR(IF($W16="","",ROUND(($W16/$W$10)*$X$10,2))),"",IF($W16="","",ROUND(($W16/$W$10)*$X$10,2))) -> 87.5 | Y16: =IF($X16="","",ROUND($X16*$Y$10,2)) -> 26.25 | Z16: =IF(ISERROR(IF($V16="","",ROUND(SUM($M16,$S16,$Y16),2))),"",IF($V16="","",ROUND(SUM($M16,$S16,$Y16),2))) -> 94.05 | AA16: =IF(ISERROR(IF($V16="","",VLOOKUP(Z16,NewTransmu,4,TRUE))),"",IF($V16="","",VLOOKUP(Z16,NewTransmu,4,TRUE))) -> 96 | AB16: =IF(ISERROR(IF(AA16="","",VLOOKUP(AA16,DESCRIPTORS,4,TRUE))),"",IF(AA16="","",VLOOKUP(AA16,DESCRIPTORS,4,TRUE))) -> Advancing | AV16: =(T16/$T$10)*100 -> 95 | AW16: =(U16/$U$10)*100 -> 85 | AX16: =(V16/$V$10)*100 -> 82.5
A17: 6 | B17: =INPUT!B17 -> Castillo, Carlo | F17: 17 | G17: 19 | H17: 18 | I17: 17 | J17: 19 | K17: =IF(COUNT($F17:$J17)=0,"",SUM($F17:$J17)) -> 90 | L17: =IF(ISERROR(IF($K17="","",ROUND(($K17/$K$10)*$L$10,2))),"",IF($K17="","",ROUND(($K17/$K$10)*$L$10,2))) -> 90 | M17: =IF($L17="","",ROUND($L17*$M$10,2)) -> 18 | N17: 49 | O17: 44 | P17: 45 | Q17: =IF(COUNT($N17:$P17)=0,"",SUM($N17:$P17)) -> 138 | R17: =IF(ISERROR(IF($Q17="","",ROUND(($Q17/$Q$10)*$R$10,2))),"",IF($Q17="","",ROUND(($Q17/$Q$10)*$R$10,2))) -> 92 | S17: =IF($R17="","",ROUND($R17*$S$10,2)) -> 46 | T17: 34 | U17: 31 | V17: 36 | W17: =IF(COUNT($T17:$V17)=0,"",SUM($T17:$V17)) -> 101 | X17: =IF(ISERROR(IF($W17="","",ROUND(($W17/$W$10)*$X$10,2))),"",IF($W17="","",ROUND(($W17/$W$10)*$X$10,2))) -> 84.17 | Y17: =IF($X17="","",ROUND($X17*$Y$10,2)) -> 25.25 | Z17: =IF(ISERROR(IF($V17="","",ROUND(SUM($M17,$S17,$Y17),2))),"",IF($V17="","",ROUND(SUM($M17,$S17,$Y17),2))) -> 89.25 | AA17: =IF(ISERROR(IF($V17="","",VLOOKUP(Z17,NewTransmu,4,TRUE))),"",IF($V17="","",VLOOKUP(Z17,NewTransmu,4,TRUE))) -> 91 | AB17: =IF(ISERROR(IF(AA17="","",VLOOKUP(AA17,DESCRIPTORS,4,TRUE))),"",IF(AA17="","",VLOOKUP(AA17,DESCRIPTORS,4,TRUE))) -> Advancing | AD17: CRITERION-REFERENCED | AE17: ST1 | AF17: ST2 | AG17: TE | AV17: =(T17/$T$10)*100 -> 85 | AW17: =(U17/$U$10)*100 -> 77.5 | AX17: =(V17/$V$10)*100 -> 90
A18: 7 | B18: =INPUT!B18 -> Cruz, Christian | F18: 17 | G18: 18 | H18: 16 | I18: 17 | J18: 17 | K18: =IF(COUNT($F18:$J18)=0,"",SUM($F18:$J18)) -> 85 | L18: =IF(ISERROR(IF($K18="","",ROUND(($K18/$K$10)*$L$10,2))),"",IF($K18="","",ROUND(($K18/$K$10)*$L$10,2))) -> 85 | M18: =IF($L18="","",ROUND($L18*$M$10,2)) -> 17 | N18: 42 | O18: 48 | P18: 43 | Q18: =IF(COUNT($N18:$P18)=0,"",SUM($N18:$P18)) -> 133 | R18: =IF(ISERROR(IF($Q18="","",ROUND(($Q18/$Q$10)*$R$10,2))),"",IF($Q18="","",ROUND(($Q18/$Q$10)*$R$10,2))) -> 88.67 | S18: =IF($R18="","",ROUND($R18*$S$10,2)) -> 44.34 | T18: 32 | U18: 36 | V18: 35 | W18: =IF(COUNT($T18:$V18)=0,"",SUM($T18:$V18)) -> 103 | X18: =IF(ISERROR(IF($W18="","",ROUND(($W18/$W$10)*$X$10,2))),"",IF($W18="","",ROUND(($W18/$W$10)*$X$10,2))) -> 85.83 | Y18: =IF($X18="","",ROUND($X18*$Y$10,2)) -> 25.75 | Z18: =IF(ISERROR(IF($V18="","",ROUND(SUM($M18,$S18,$Y18),2))),"",IF($V18="","",ROUND(SUM($M18,$S18,$Y18),2))) -> 87.09 | AA18: =IF(ISERROR(IF($V18="","",VLOOKUP(Z18,NewTransmu,4,TRUE))),"",IF($V18="","",VLOOKUP(Z18,NewTransmu,4,TRUE))) -> 89 | AB18: =IF(ISERROR(IF(AA18="","",VLOOKUP(AA18,DESCRIPTORS,4,TRUE))),"",IF(AA18="","",VLOOKUP(AA18,DESCRIPTORS,4,TRUE))) -> Benchmarking | AD18: Got 75% & above | AE18: =COUNTIF(AV12:AV112,">=75") -> 75 | AF18: =COUNTIF(AW12:AW112,">=75") -> 77 | AG18: =COUNTIF(AX12:AX112,">=75") -> 79 | AV18: =(T18/$T$10)*100 -> 80 | AW18: =(U18/$U$10)*100 -> 90 | AX18: =(V18/$V$10)*100 -> 87.5
A19: 8 | B19: =INPUT!B19 -> Dela Cruz, Daniel | F19: 19 | G19: 20 | H19: 20 | I19: 19 | J19: 20 | K19: =IF(COUNT($F19:$J19)=0,"",SUM($F19:$J19)) -> 98 | L19: =IF(ISERROR(IF($K19="","",ROUND(($K19/$K$10)*$L$10,2))),"",IF($K19="","",ROUND(($K19/$K$10)*$L$10,2))) -> 98 | M19: =IF($L19="","",ROUND($L19*$M$10,2)) -> 19.6 | N19: 48 | O19: 50 | P19: 50 | Q19: =IF(COUNT($N19:$P19)=0,"",SUM($N19:$P19)) -> 148 | R19: =IF(ISERROR(IF($Q19="","",ROUND(($Q19/$Q$10)*$R$10,2))),"",IF($Q19="","",ROUND(($Q19/$Q$10)*$R$10,2))) -> 98.67 | S19: =IF($R19="","",ROUND($R19*$S$10,2)) -> 49.34 | T19: 39 | U19: 39 | V19: 37 | W19: =IF(COUNT($T19:$V19)=0,"",SUM($T19:$V19)) -> 115 | X19: =IF(ISERROR(IF($W19="","",ROUND(($W19/$W$10)*$X$10,2))),"",IF($W19="","",ROUND(($W19/$W$10)*$X$10,2))) -> 95.83 | Y19: =IF($X19="","",ROUND($X19*$Y$10,2)) -> 28.75 | Z19: =IF(ISERROR(IF($V19="","",ROUND(SUM($M19,$S19,$Y19),2))),"",IF($V19="","",ROUND(SUM($M19,$S19,$Y19),2))) -> 97.69 | AA19: =IF(ISERROR(IF($V19="","",VLOOKUP(Z19,NewTransmu,4,TRUE))),"",IF($V19="","",VLOOKUP(Z19,NewTransmu,4,TRUE))) -> 99 | AB19: =IF(ISERROR(IF(AA19="","",VLOOKUP(AA19,DESCRIPTORS,4,TRUE))),"",IF(AA19="","",VLOOKUP(AA19,DESCRIPTORS,4,TRUE))) -> Advancing | AD19: Percentage | AE19: =IFERROR(AE18/AE14,"") -> 0.75 | AF19: =IFERROR(AF18/AF14,"") -> 0.77 | AG19: =IFERROR(AG18/AG14,"") -> 0.79 | AV19: =(T19/$T$10)*100 -> 97.5 | AW19: =(U19/$U$10)*100 -> 97.5 | AX19: =(V19/$V$10)*100 -> 92.5
A20: 9 | B20: =INPUT!B20 -> Diaz, Darren | F20: 19 | G20: 19 | H20: 18 | I20: 19 | J20: 18 | K20: =IF(COUNT($F20:$J20)=0,"",SUM($F20:$J20)) -> 93 | L20: =IF(ISERROR(IF($K20="","",ROUND(($K20/$K$10)*$L$10,2))),"",IF($K20="","",ROUND(($K20/$K$10)*$L$10,2))) -> 93 | M20: =IF($L20="","",ROUND($L20*$M$10,2)) -> 18.6 | N20: 46 | O20: 47 | P20: 45 | Q20: =IF(COUNT($N20:$P20)=0,"",SUM($N20:$P20)) -> 138 | R20: =IF(ISERROR(IF($Q20="","",ROUND(($Q20/$Q$10)*$R$10,2))),"",IF($Q20="","",ROUND(($Q20/$Q$10)*$R$10,2))) -> 92 | S20: =IF($R20="","",ROUND($R20*$S$10,2)) -> 46 | T20: 35 | U20: 33 | V20: 34 | W20: =IF(COUNT($T20:$V20)=0,"",SUM($T20:$V20)) -> 102 | X20: =IF(ISERROR(IF($W20="","",ROUND(($W20/$W$10)*$X$10,2))),"",IF($W20="","",ROUND(($W20/$W$10)*$X$10,2))) -> 85 | Y20: =IF($X20="","",ROUND($X20*$Y$10,2)) -> 25.5 | Z20: =IF(ISERROR(IF($V20="","",ROUND(SUM($M20,$S20,$Y20),2))),"",IF($V20="","",ROUND(SUM($M20,$S20,$Y20),2))) -> 90.1 | AA20: =IF(ISERROR(IF($V20="","",VLOOKUP(Z20,NewTransmu,4,TRUE))),"",IF($V20="","",VLOOKUP(Z20,NewTransmu,4,TRUE))) -> 92 | AB20: =IF(ISERROR(IF(AA20="","",VLOOKUP(AA20,DESCRIPTORS,4,TRUE))),"",IF(AA20="","",VLOOKUP(AA20,DESCRIPTORS,4,TRUE))) -> Advancing | AD20: Got below 75% | AE20: =AE14-AE18 -> 25 | AF20: =AF14-AF18 -> 23 | AG20: =AG14-AG18 -> 21 | AV20: =(T20/$T$10)*100 -> 87.5 | AW20: =(U20/$U$10)*100 -> 82.5 | AX20: =(V20/$V$10)*100 -> 85
A21: 10 | B21: =INPUT!B21 -> Evangelista, Diego | F21: 17 | G21: 15 | H21: 16 | I21: 16 | J21: 17 | K21: =IF(COUNT($F21:$J21)=0,"",SUM($F21:$J21)) -> 81 | L21: =IF(ISERROR(IF($K21="","",ROUND(($K21/$K$10)*$L$10,2))),"",IF($K21="","",ROUND(($K21/$K$10)*$L$10,2))) -> 81 | M21: =IF($L21="","",ROUND($L21*$M$10,2)) -> 16.2 | N21: 45 | O21: 40 | P21: 41 | Q21: =IF(COUNT($N21:$P21)=0,"",SUM($N21:$P21)) -> 126 | R21: =IF(ISERROR(IF($Q21="","",ROUND(($Q21/$Q$10)*$R$10,2))),"",IF($Q21="","",ROUND(($Q21/$Q$10)*$R$10,2))) -> 84 | S21: =IF($R21="","",ROUND($R21*$S$10,2)) -> 42 | T21: 31 | U21: 34 | V21: 29 | W21: =IF(COUNT($T21:$V21)=0,"",SUM($T21:$V21)) -> 94 | X21: =IF(ISERROR(IF($W21="","",ROUND(($W21/$W$10)*$X$10,2))),"",IF($W21="","",ROUND(($W21/$W$10)*$X$10,2))) -> 78.33 | Y21: =IF($X21="","",ROUND($X21*$Y$10,2)) -> 23.5 | Z21: =IF(ISERROR(IF($V21="","",ROUND(SUM($M21,$S21,$Y21),2))),"",IF($V21="","",ROUND(SUM($M21,$S21,$Y21),2))) -> 81.7 | AA21: =IF(ISERROR(IF($V21="","",VLOOKUP(Z21,NewTransmu,4,TRUE))),"",IF($V21="","",VLOOKUP(Z21,NewTransmu,4,TRUE))) -> 83 | AB21: =IF(ISERROR(IF(AA21="","",VLOOKUP(AA21,DESCRIPTORS,4,TRUE))),"",IF(AA21="","",VLOOKUP(AA21,DESCRIPTORS,4,TRUE))) -> Benchmarking | AD21: Percentage | AE21: =IFERROR(1-AE19,"") -> 0.25 | AF21: =IFERROR(1-AF19,"") -> 0.23 | AG21: =IFERROR(1-AG19,"") -> 0.21 | AV21: =(T21/$T$10)*100 -> 77.5 | AW21: =(U21/$U$10)*100 -> 85 | AX21: =(V21/$V$10)*100 -> 72.5
A22: 11 | B22: =INPUT!B22 -> Fernandez, Ethan | F22: 14 | G22: 13 | H22: 12 | I22: 13 | J22: 12 | K22: =IF(COUNT($F22:$J22)=0,"",SUM($F22:$J22)) -> 64 | L22: =IF(ISERROR(IF($K22="","",ROUND(($K22/$K$10)*$L$10,2))),"",IF($K22="","",ROUND(($K22/$K$10)*$L$10,2))) -> 64 | M22: =IF($L22="","",ROUND($L22*$M$10,2)) -> 12.8 | N22: 34 | O22: 36 | P22: 32 | Q22: =IF(COUNT($N22:$P22)=0,"",SUM($N22:$P22)) -> 102 | R22: =IF(ISERROR(IF($Q22="","",ROUND(($Q22/$Q$10)*$R$10,2))),"",IF($Q22="","",ROUND(($Q22/$Q$10)*$R$10,2))) -> 68 | S22: =IF($R22="","",ROUND($R22*$S$10,2)) -> 34 | T22: 24 | U22: 26 | V22: 25 | W22: =IF(COUNT($T22:$V22)=0,"",SUM($T22:$V22)) -> 75 | X22: =IF(ISERROR(IF($W22="","",ROUND(($W22/$W$10)*$X$10,2))),"",IF($W22="","",ROUND(($W22/$W$10)*$X$10,2))) -> 62.5 | Y22: =IF($X22="","",ROUND($X22*$Y$10,2)) -> 18.75 | Z22: =IF(ISERROR(IF($V22="","",ROUND(SUM($M22,$S22,$Y22),2))),"",IF($V22="","",ROUND(SUM($M22,$S22,$Y22),2))) -> 65.55 | AA22: =IF(ISERROR(IF($V22="","",VLOOKUP(Z22,NewTransmu,4,TRUE))),"",IF($V22="","",VLOOKUP(Z22,NewTransmu,4,TRUE))) -> 72 | AB22: =IF(ISERROR(IF(AA22="","",VLOOKUP(AA22,DESCRIPTORS,4,TRUE))),"",IF(AA22="","",VLOOKUP(AA22,DESCRIPTORS,4,TRUE))) -> Developing | AV22: =(T22/$T$10)*100 -> 60 | AW22: =(U22/$U$10)*100 -> 65 | AX22: =(V22/$V$10)*100 -> 62.5
A23: 12 | B23: =INPUT!B23 -> Garcia, Gabriel | F23: 15 | G23: 15 | H23: 16 | I23: 15 | J23: 15 | K23: =IF(COUNT($F23:$J23)=0,"",SUM($F23:$J23)) -> 76 | L23: =IF(ISERROR(IF($K23="","",ROUND(($K23/$K$10)*$L$10,2))),"",IF($K23="","",ROUND(($K23/$K$10)*$L$10,2))) -> 76 | M23: =IF($L23="","",ROUND($L23*$M$10,2)) -> 15.2 | N23: 42 | O23: 37 | P23: 42 | Q23: =IF(COUNT($N23:$P23)=0,"",SUM($N23:$P23)) -> 121 | R23: =IF(ISERROR(IF($Q23="","",ROUND(($Q23/$Q$10)*$R$10,2))),"",IF($Q23="","",ROUND(($Q23/$Q$10)*$R$10,2))) -> 80.67 | S23: =IF($R23="","",ROUND($R23*$S$10,2)) -> 40.34 | T23: 28 | U23: 30 | V23: 28 | W23: =IF(COUNT($T23:$V23)=0,"",SUM($T23:$V23)) -> 86 | X23: =IF(ISERROR(IF($W23="","",ROUND(($W23/$W$10)*$X$10,2))),"",IF($W23="","",ROUND(($W23/$W$10)*$X$10,2))) -> 71.67 | Y23: =IF($X23="","",ROUND($X23*$Y$10,2)) -> 21.5 | Z23: =IF(ISERROR(IF($V23="","",ROUND(SUM($M23,$S23,$Y23),2))),"",IF($V23="","",ROUND(SUM($M23,$S23,$Y23),2))) -> 77.04 | AA23: =IF(ISERROR(IF($V23="","",VLOOKUP(Z23,NewTransmu,4,TRUE))),"",IF($V23="","",VLOOKUP(Z23,NewTransmu,4,TRUE))) -> 79 | AB23: =IF(ISERROR(IF(AA23="","",VLOOKUP(AA23,DESCRIPTORS,4,TRUE))),"",IF(AA23="","",VLOOKUP(AA23,DESCRIPTORS,4,TRUE))) -> Connecting | AD23: NORM-REFERENCED | AE23: ST1 | AF23: ST2 | AG23: TE | AV23: =(T23/$T$10)*100 -> 70 | AW23: =(U23/$U$10)*100 -> 75 | AX23: =(V23/$V$10)*100 -> 70
A24: 13 | B24: =INPUT!B24 -> Gonzales, Harold | F24: 17 | G24: 18 | H24: 19 | I24: 18 | J24: 18 | K24: =IF(COUNT($F24:$J24)=0,"",SUM($F24:$J24)) -> 90 | L24: =IF(ISERROR(IF($K24="","",ROUND(($K24/$K$10)*$L$10,2))),"",IF($K24="","",ROUND(($K24/$K$10)*$L$10,2))) -> 90 | M24: =IF($L24="","",ROUND($L24*$M$10,2)) -> 18 | N24: 45 | O24: 45 | P24: 49 | Q24: =IF(COUNT($N24:$P24)=0,"",SUM($N24:$P24)) -> 139 | R24: =IF(ISERROR(IF($Q24="","",ROUND(($Q24/$Q$10)*$R$10,2))),"",IF($Q24="","",ROUND(($Q24/$Q$10)*$R$10,2))) -> 92.67 | S24: =IF($R24="","",ROUND($R24*$S$10,2)) -> 46.34 | T24: 35 | U24: 33 | V24: 34 | W24: =IF(COUNT($T24:$V24)=0,"",SUM($T24:$V24)) -> 102 | X24: =IF(ISERROR(IF($W24="","",ROUND(($W24/$W$10)*$X$10,2))),"",IF($W24="","",ROUND(($W24/$W$10)*$X$10,2))) -> 85 | Y24: =IF($X24="","",ROUND($X24*$Y$10,2)) -> 25.5 | Z24: =IF(ISERROR(IF($V24="","",ROUND(SUM($M24,$S24,$Y24),2))),"",IF($V24="","",ROUND(SUM($M24,$S24,$Y24),2))) -> 89.84 | AA24: =IF(ISERROR(IF($V24="","",VLOOKUP(Z24,NewTransmu,4,TRUE))),"",IF($V24="","",VLOOKUP(Z24,NewTransmu,4,TRUE))) -> 91 | AB24: =IF(ISERROR(IF(AA24="","",VLOOKUP(AA24,DESCRIPTORS,4,TRUE))),"",IF(AA24="","",VLOOKUP(AA24,DESCRIPTORS,4,TRUE))) -> Advancing | AD24: Mean | AE24: =IFERROR(AVERAGE(T12:T112),"") -> 31.63 | AF24: =IFERROR(AVERAGE(U12:U112),"") -> 31.66 | AG24: =IFERROR(AVERAGE(V12:V112),"") -> 31.73 | AV24: =(T24/$T$10)*100 -> 87.5 | AW24: =(U24/$U$10)*100 -> 82.5 | AX24: =(V24/$V$10)*100 -> 85
A25: 14 | B25: =INPUT!B25 -> Hernandez, Ivan | F25: 18 | G25: 18 | H25: 18 | I25: 16 | J25: 18 | K25: =IF(COUNT($F25:$J25)=0,"",SUM($F25:$J25)) -> 88 | L25: =IF(ISERROR(IF($K25="","",ROUND(($K25/$K$10)*$L$10,2))),"",IF($K25="","",ROUND(($K25/$K$10)*$L$10,2))) -> 88 | M25: =IF($L25="","",ROUND($L25*$M$10,2)) -> 17.6 | N25: 44 | O25: 45 | P25: 44 | Q25: =IF(COUNT($N25:$P25)=0,"",SUM($N25:$P25)) -> 133 | R25: =IF(ISERROR(IF($Q25="","",ROUND(($Q25/$Q$10)*$R$10,2))),"",IF($Q25="","",ROUND(($Q25/$Q$10)*$R$10,2))) -> 88.67 | S25: =IF($R25="","",ROUND($R25*$S$10,2)) -> 44.34 | T25: 32 | U25: 31 | V25: 31 | W25: =IF(COUNT($T25:$V25)=0,"",SUM($T25:$V25)) -> 94 | X25: =IF(ISERROR(IF($W25="","",ROUND(($W25/$W$10)*$X$10,2))),"",IF($W25="","",ROUND(($W25/$W$10)*$X$10,2))) -> 78.33 | Y25: =IF($X25="","",ROUND($X25*$Y$10,2)) -> 23.5 | Z25: =IF(ISERROR(IF($V25="","",ROUND(SUM($M25,$S25,$Y25),2))),"",IF($V25="","",ROUND(SUM($M25,$S25,$Y25),2))) -> 85.44 | AA25: =IF(ISERROR(IF($V25="","",VLOOKUP(Z25,NewTransmu,4,TRUE))),"",IF($V25="","",VLOOKUP(Z25,NewTransmu,4,TRUE))) -> 87 | AB25: =IF(ISERROR(IF(AA25="","",VLOOKUP(AA25,DESCRIPTORS,4,TRUE))),"",IF(AA25="","",VLOOKUP(AA25,DESCRIPTORS,4,TRUE))) -> Benchmarking | AD25: Median | AE25: =IFERROR(MEDIAN(T12:T112),"") -> 33 | AF25: =IFERROR(MEDIAN(U12:U112),"") -> 32 | AG25: =IFERROR(MEDIAN(V12:V112),"") -> 32.5 | AV25: =(T25/$T$10)*100 -> 80 | AW25: =(U25/$U$10)*100 -> 77.5 | AX25: =(V25/$V$10)*100 -> 77.5
A26: 15 | B26: =INPUT!B26 -> Ilagan, Jacob | F26: 9 | G26: 10 | H26: 11 | I26: 9 | J26: 9 | K26: =IF(COUNT($F26:$J26)=0,"",SUM($F26:$J26)) -> 48 | L26: =IF(ISERROR(IF($K26="","",ROUND(($K26/$K$10)*$L$10,2))),"",IF($K26="","",ROUND(($K26/$K$10)*$L$10,2))) -> 48 | M26: =IF($L26="","",ROUND($L26*$M$10,2)) -> 9.6 | N26: 24 | O26: 23 | P26: 24 | Q26: =IF(COUNT($N26:$P26)=0,"",SUM($N26:$P26)) -> 71 | R26: =IF(ISERROR(IF($Q26="","",ROUND(($Q26/$Q$10)*$R$10,2))),"",IF($Q26="","",ROUND(($Q26/$Q$10)*$R$10,2))) -> 47.33 | S26: =IF($R26="","",ROUND($R26*$S$10,2)) -> 23.67 | T26: 20 | U26: 17 | V26: 21 | W26: =IF(COUNT($T26:$V26)=0,"",SUM($T26:$V26)) -> 58 | X26: =IF(ISERROR(IF($W26="","",ROUND(($W26/$W$10)*$X$10,2))),"",IF($W26="","",ROUND(($W26/$W$10)*$X$10,2))) -> 48.33 | Y26: =IF($X26="","",ROUND($X26*$Y$10,2)) -> 14.5 | Z26: =IF(ISERROR(IF($V26="","",ROUND(SUM($M26,$S26,$Y26),2))),"",IF($V26="","",ROUND(SUM($M26,$S26,$Y26),2))) -> 47.77 | AA26: =IF(ISERROR(IF($V26="","",VLOOKUP(Z26,NewTransmu,4,TRUE))),"",IF($V26="","",VLOOKUP(Z26,NewTransmu,4,TRUE))) -> 63 | AB26: =IF(ISERROR(IF(AA26="","",VLOOKUP(AA26,DESCRIPTORS,4,TRUE))),"",IF(AA26="","",VLOOKUP(AA26,DESCRIPTORS,4,TRUE))) -> Emerging | AD26: SD | AE26: =IFERROR(_xlfn.STDEV.S(T12:T112),"") -> 5.1574306 | AF26: =_xlfn.STDEV.S(U12:U112) -> 5.0875566 | AG26: =_xlfn.STDEV.S(V12:V112) -> 4.7881482 | AV26: =(T26/$T$10)*100 -> 50 | AW26: =(U26/$U$10)*100 -> 42.5 | AX26: =(V26/$V$10)*100 -> 52.5
A27: 16 | B27: =INPUT!B27 -> Jimenez, James | F27: 17 | G27: 16 | H27: 17 | I27: 17 | J27: 17 | K27: =IF(COUNT($F27:$J27)=0,"",SUM($F27:$J27)) -> 84 | L27: =IF(ISERROR(IF($K27="","",ROUND(($K27/$K$10)*$L$10,2))),"",IF($K27="","",ROUND(($K27/$K$10)*$L$10,2))) -> 84 | M27: =IF($L27="","",ROUND($L27*$M$10,2)) -> 16.8 | N27: 48 | O27: 48 | P27: 43 | Q27: =IF(COUNT($N27:$P27)=0,"",SUM($N27:$P27)) -> 139 | R27: =IF(ISERROR(IF($Q27="","",ROUND(($Q27/$Q$10)*$R$10,2))),"",IF($Q27="","",ROUND(($Q27/$Q$10)*$R$10,2))) -> 92.67 | S27: =IF($R27="","",ROUND($R27*$S$10,2)) -> 46.34 | T27: 35 | U27: 34 | V27: 36 | W27: =IF(COUNT($T27:$V27)=0,"",SUM($T27:$V27)) -> 105 | X27: =IF(ISERROR(IF($W27="","",ROUND(($W27/$W$10)*$X$10,2))),"",IF($W27="","",ROUND(($W27/$W$10)*$X$10,2))) -> 87.5 | Y27: =IF($X27="","",ROUND($X27*$Y$10,2)) -> 26.25 | Z27: =IF(ISERROR(IF($V27="","",ROUND(SUM($M27,$S27,$Y27),2))),"",IF($V27="","",ROUND(SUM($M27,$S27,$Y27),2))) -> 89.39 | AA27: =IF(ISERROR(IF($V27="","",VLOOKUP(Z27,NewTransmu,4,TRUE))),"",IF($V27="","",VLOOKUP(Z27,NewTransmu,4,TRUE))) -> 91 | AB27: =IF(ISERROR(IF(AA27="","",VLOOKUP(AA27,DESCRIPTORS,4,TRUE))),"",IF(AA27="","",VLOOKUP(AA27,DESCRIPTORS,4,TRUE))) -> Advancing | AD27: MPS/PL | AE27: =IFERROR(AE24/AE15,"") -> 0.79075 | AF27: =IFERROR(AF24/AF15,"") -> 0.7915 | AG27: =IFERROR(AG24/AG15,"") -> 0.79325 | AV27: =(T27/$T$10)*100 -> 87.5 | AW27: =(U27/$U$10)*100 -> 85 | AX27: =(V27/$V$10)*100 -> 90
A28: 17 | B28: =INPUT!B28 -> Lacson, Jared | F28: 17 | G28: 17 | H28: 19 | I28: 18 | J28: 19 | K28: =IF(COUNT($F28:$J28)=0,"",SUM($F28:$J28)) -> 90 | L28: =IF(ISERROR(IF($K28="","",ROUND(($K28/$K$10)*$L$10,2))),"",IF($K28="","",ROUND(($K28/$K$10)*$L$10,2))) -> 90 | M28: =IF($L28="","",ROUND($L28*$M$10,2)) -> 18 | N28: 47 | O28: 47 | P28: 46 | Q28: =IF(COUNT($N28:$P28)=0,"",SUM($N28:$P28)) -> 140 | R28: =IF(ISERROR(IF($Q28="","",ROUND(($Q28/$Q$10)*$R$10,2))),"",IF($Q28="","",ROUND(($Q28/$Q$10)*$R$10,2))) -> 93.33 | S28: =IF($R28="","",ROUND($R28*$S$10,2)) -> 46.67 | T28: 33 | U28: 33 | V28: 36 | W28: =IF(COUNT($T28:$V28)=0,"",SUM($T28:$V28)) -> 102 | X28: =IF(ISERROR(IF($W28="","",ROUND(($W28/$W$10)*$X$10,2))),"",IF($W28="","",ROUND(($W28/$W$10)*$X$10,2))) -> 85 | Y28: =IF($X28="","",ROUND($X28*$Y$10,2)) -> 25.5 | Z28: =IF(ISERROR(IF($V28="","",ROUND(SUM($M28,$S28,$Y28),2))),"",IF($V28="","",ROUND(SUM($M28,$S28,$Y28),2))) -> 90.17 | AA28: =IF(ISERROR(IF($V28="","",VLOOKUP(Z28,NewTransmu,4,TRUE))),"",IF($V28="","",VLOOKUP(Z28,NewTransmu,4,TRUE))) -> 92 | AB28: =IF(ISERROR(IF(AA28="","",VLOOKUP(AA28,DESCRIPTORS,4,TRUE))),"",IF(AA28="","",VLOOKUP(AA28,DESCRIPTORS,4,TRUE))) -> Advancing | AV28: =(T28/$T$10)*100 -> 82.5 | AW28: =(U28/$U$10)*100 -> 82.5 | AX28: =(V28/$V$10)*100 -> 90
A29: 18 | B29: =INPUT!B29 -> Lim, Jericho | F29: 19 | G29: 18 | H29: 18 | I29: 19 | J29: 18 | K29: =IF(COUNT($F29:$J29)=0,"",SUM($F29:$J29)) -> 92 | L29: =IF(ISERROR(IF($K29="","",ROUND(($K29/$K$10)*$L$10,2))),"",IF($K29="","",ROUND(($K29/$K$10)*$L$10,2))) -> 92 | M29: =IF($L29="","",ROUND($L29*$M$10,2)) -> 18.4 | N29: 44 | O29: 49 | P29: 47 | Q29: =IF(COUNT($N29:$P29)=0,"",SUM($N29:$P29)) -> 140 | R29: =IF(ISERROR(IF($Q29="","",ROUND(($Q29/$Q$10)*$R$10,2))),"",IF($Q29="","",ROUND(($Q29/$Q$10)*$R$10,2))) -> 93.33 | S29: =IF($R29="","",ROUND($R29*$S$10,2)) -> 46.67 | T29: 37 | U29: 36 | V29: 37 | W29: =IF(COUNT($T29:$V29)=0,"",SUM($T29:$V29)) -> 110 | X29: =IF(ISERROR(IF($W29="","",ROUND(($W29/$W$10)*$X$10,2))),"",IF($W29="","",ROUND(($W29/$W$10)*$X$10,2))) -> 91.67 | Y29: =IF($X29="","",ROUND($X29*$Y$10,2)) -> 27.5 | Z29: =IF(ISERROR(IF($V29="","",ROUND(SUM($M29,$S29,$Y29),2))),"",IF($V29="","",ROUND(SUM($M29,$S29,$Y29),2))) -> 92.57 | AA29: =IF(ISERROR(IF($V29="","",VLOOKUP(Z29,NewTransmu,4,TRUE))),"",IF($V29="","",VLOOKUP(Z29,NewTransmu,4,TRUE))) -> 94 | AB29: =IF(ISERROR(IF(AA29="","",VLOOKUP(AA29,DESCRIPTORS,4,TRUE))),"",IF(AA29="","",VLOOKUP(AA29,DESCRIPTORS,4,TRUE))) -> Advancing | AD29: OTHER INFO | AE29: ST1 | AF29: ST2 | AG29: TE | AV29: =(T29/$T$10)*100 -> 92.5 | AW29: =(U29/$U$10)*100 -> 90 | AX29: =(V29/$V$10)*100 -> 92.5
A30: 19 | B30: =INPUT!B30 -> Manalo, Joaquin | F30: 18 | G30: 18 | H30: 18 | I30: 18 | J30: 20 | K30: =IF(COUNT($F30:$J30)=0,"",SUM($F30:$J30)) -> 92 | L30: =IF(ISERROR(IF($K30="","",ROUND(($K30/$K$10)*$L$10,2))),"",IF($K30="","",ROUND(($K30/$K$10)*$L$10,2))) -> 92 | M30: =IF($L30="","",ROUND($L30*$M$10,2)) -> 18.4 | N30: 50 | O30: 47 | P30: 46 | Q30: =IF(COUNT($N30:$P30)=0,"",SUM($N30:$P30)) -> 143 | R30: =IF(ISERROR(IF($Q30="","",ROUND(($Q30/$Q$10)*$R$10,2))),"",IF($Q30="","",ROUND(($Q30/$Q$10)*$R$10,2))) -> 95.33 | S30: =IF($R30="","",ROUND($R30*$S$10,2)) -> 47.67 | T30: 36 | U30: 36 | V30: 38 | W30: =IF(COUNT($T30:$V30)=0,"",SUM($T30:$V30)) -> 110 | X30: =IF(ISERROR(IF($W30="","",ROUND(($W30/$W$10)*$X$10,2))),"",IF($W30="","",ROUND(($W30/$W$10)*$X$10,2))) -> 91.67 | Y30: =IF($X30="","",ROUND($X30*$Y$10,2)) -> 27.5 | Z30: =IF(ISERROR(IF($V30="","",ROUND(SUM($M30,$S30,$Y30),2))),"",IF($V30="","",ROUND(SUM($M30,$S30,$Y30),2))) -> 93.57 | AA30: =IF(ISERROR(IF($V30="","",VLOOKUP(Z30,NewTransmu,4,TRUE))),"",IF($V30="","",VLOOKUP(Z30,NewTransmu,4,TRUE))) -> 95 | AB30: =IF(ISERROR(IF(AA30="","",VLOOKUP(AA30,DESCRIPTORS,4,TRUE))),"",IF(AA30="","",VLOOKUP(AA30,DESCRIPTORS,4,TRUE))) -> Advancing | AD30: Highest Score | AE30: =IF(COUNTA(T12:T112)=0,"",MAX(T12:T112)) -> 40 | AF30: =IF(COUNTA(U12:U112)=0,"",MAX(U12:U112)) -> 40 | AG30: =IF(COUNTA(V12:V112)=0,"",MAX(V12:V112)) -> 39 | AV30: =(T30/$T$10)*100 -> 90 | AW30: =(U30/$U$10)*100 -> 90 | AX30: =(V30/$V$10)*100 -> 95
A31: 20 | B31: =INPUT!B31 -> Mendoza, Joshua | F31: 17 | G31: 17 | H31: 17 | I31: 17 | J31: 15 | K31: =IF(COUNT($F31:$J31)=0,"",SUM($F31:$J31)) -> 83 | L31: =IF(ISERROR(IF($K31="","",ROUND(($K31/$K$10)*$L$10,2))),"",IF($K31="","",ROUND(($K31/$K$10)*$L$10,2))) -> 83 | M31: =IF($L31="","",ROUND($L31*$M$10,2)) -> 16.6 | N31: 47 | O31: 40 | P31: 46 | Q31: =IF(COUNT($N31:$P31)=0,"",SUM($N31:$P31)) -> 133 | R31: =IF(ISERROR(IF($Q31="","",ROUND(($Q31/$Q$10)*$R$10,2))),"",IF($Q31="","",ROUND(($Q31/$Q$10)*$R$10,2))) -> 88.67 | S31: =IF($R31="","",ROUND($R31*$S$10,2)) -> 44.34 | T31: 30 | U31: 31 | V31: 33 | W31: =IF(COUNT($T31:$V31)=0,"",SUM($T31:$V31)) -> 94 | X31: =IF(ISERROR(IF($W31="","",ROUND(($W31/$W$10)*$X$10,2))),"",IF($W31="","",ROUND(($W31/$W$10)*$X$10,2))) -> 78.33 | Y31: =IF($X31="","",ROUND($X31*$Y$10,2)) -> 23.5 | Z31: =IF(ISERROR(IF($V31="","",ROUND(SUM($M31,$S31,$Y31),2))),"",IF($V31="","",ROUND(SUM($M31,$S31,$Y31),2))) -> 84.44 | AA31: =IF(ISERROR(IF($V31="","",VLOOKUP(Z31,NewTransmu,4,TRUE))),"",IF($V31="","",VLOOKUP(Z31,NewTransmu,4,TRUE))) -> 86 | AB31: =IF(ISERROR(IF(AA31="","",VLOOKUP(AA31,DESCRIPTORS,4,TRUE))),"",IF(AA31="","",VLOOKUP(AA31,DESCRIPTORS,4,TRUE))) -> Benchmarking | AD31: Lowest Score | AE31: =IF(COUNTA(T12:T112)=0,"",MIN(T12:T112)) -> 14 | AF31: =IF(COUNTA(U12:U112)=0,"",MIN(U12:U112)) -> 16 | AG31: =IF(COUNTA(V12:V112)=0,"",MIN(V12:V112)) -> 17 | AV31: =(T31/$T$10)*100 -> 75 | AW31: =(U31/$U$10)*100 -> 77.5 | AX31: =(V31/$V$10)*100 -> 82.5
A32: 21 | B32: =INPUT!B32 -> Navarro, Lance | F32: 20 | G32: 20 | H32: 20 | I32: 19 | J32: 18 | K32: =IF(COUNT($F32:$J32)=0,"",SUM($F32:$J32)) -> 97 | L32: =IF(ISERROR(IF($K32="","",ROUND(($K32/$K$10)*$L$10,2))),"",IF($K32="","",ROUND(($K32/$K$10)*$L$10,2))) -> 97 | M32: =IF($L32="","",ROUND($L32*$M$10,2)) -> 19.4 | N32: 48 | O32: 49 | P32: 50 | Q32: =IF(COUNT($N32:$P32)=0,"",SUM($N32:$P32)) -> 147 | R32: =IF(ISERROR(IF($Q32="","",ROUND(($Q32/$Q$10)*$R$10,2))),"",IF($Q32="","",ROUND(($Q32/$Q$10)*$R$10,2))) -> 98 | S32: =IF($R32="","",ROUND($R32*$S$10,2)) -> 49 | T32: 39 | U32: 39 | V32: 38 | W32: =IF(COUNT($T32:$V32)=0,"",SUM($T32:$V32)) -> 116 | X32: =IF(ISERROR(IF($W32="","",ROUND(($W32/$W$10)*$X$10,2))),"",IF($W32="","",ROUND(($W32/$W$10)*$X$10,2))) -> 96.67 | Y32: =IF($X32="","",ROUND($X32*$Y$10,2)) -> 29 | Z32: =IF(ISERROR(IF($V32="","",ROUND(SUM($M32,$S32,$Y32),2))),"",IF($V32="","",ROUND(SUM($M32,$S32,$Y32),2))) -> 97.4 | AA32: =IF(ISERROR(IF($V32="","",VLOOKUP(Z32,NewTransmu,4,TRUE))),"",IF($V32="","",VLOOKUP(Z32,NewTransmu,4,TRUE))) -> 98 | AB32: =IF(ISERROR(IF(AA32="","",VLOOKUP(AA32,DESCRIPTORS,4,TRUE))),"",IF(AA32="","",VLOOKUP(AA32,DESCRIPTORS,4,TRUE))) -> Advancing | AD32: Total Score | AE32: =IF(COUNTA(T12:T112)=0,"",SUM(T12:T112)) -> 3163 | AF32: =IF(COUNTA(U12:U112)=0,"",SUM(U12:U112)) -> 3166 | AG32: =IF(COUNTA(V12:V112)=0,"",SUM(V12:V112)) -> 3173 | AV32: =(T32/$T$10)*100 -> 97.5 | AW32: =(U32/$U$10)*100 -> 97.5 | AX32: =(V32/$V$10)*100 -> 95
A33: 22 | B33: =INPUT!B33 -> Ocampo, Luis | F33: 15 | G33: 16 | H33: 17 | I33: 16 | J33: 15 | K33: =IF(COUNT($F33:$J33)=0,"",SUM($F33:$J33)) -> 79 | L33: =IF(ISERROR(IF($K33="","",ROUND(($K33/$K$10)*$L$10,2))),"",IF($K33="","",ROUND(($K33/$K$10)*$L$10,2))) -> 79 | M33: =IF($L33="","",ROUND($L33*$M$10,2)) -> 15.8 | N33: 45 | O33: 42 | P33: 45 | Q33: =IF(COUNT($N33:$P33)=0,"",SUM($N33:$P33)) -> 132 | R33: =IF(ISERROR(IF($Q33="","",ROUND(($Q33/$Q$10)*$R$10,2))),"",IF($Q33="","",ROUND(($Q33/$Q$10)*$R$10,2))) -> 88 | S33: =IF($R33="","",ROUND($R33*$S$10,2)) -> 44 | T33: 30 | U33: 29 | V33: 31 | W33: =IF(COUNT($T33:$V33)=0,"",SUM($T33:$V33)) -> 90 | X33: =IF(ISERROR(IF($W33="","",ROUND(($W33/$W$10)*$X$10,2))),"",IF($W33="","",ROUND(($W33/$W$10)*$X$10,2))) -> 75 | Y33: =IF($X33="","",ROUND($X33*$Y$10,2)) -> 22.5 | Z33: =IF(ISERROR(IF($V33="","",ROUND(SUM($M33,$S33,$Y33),2))),"",IF($V33="","",ROUND(SUM($M33,$S33,$Y33),2))) -> 82.3 | AA33: =IF(ISERROR(IF($V33="","",VLOOKUP(Z33,NewTransmu,4,TRUE))),"",IF($V33="","",VLOOKUP(Z33,NewTransmu,4,TRUE))) -> 84 | AB33: =IF(ISERROR(IF(AA33="","",VLOOKUP(AA33,DESCRIPTORS,4,TRUE))),"",IF(AA33="","",VLOOKUP(AA33,DESCRIPTORS,4,TRUE))) -> Benchmarking | AV33: =(T33/$T$10)*100 -> 75 | AW33: =(U33/$U$10)*100 -> 72.5 | AX33: =(V33/$V$10)*100 -> 77.5
A34: 23 | B34: =INPUT!B34 -> Ortega, Marco | F34: 17 | G34: 17 | H34: 19 | I34: 17 | J34: 19 | K34: =IF(COUNT($F34:$J34)=0,"",SUM($F34:$J34)) -> 89 | L34: =IF(ISERROR(IF($K34="","",ROUND(($K34/$K$10)*$L$10,2))),"",IF($K34="","",ROUND(($K34/$K$10)*$L$10,2))) -> 89 | M34: =IF($L34="","",ROUND($L34*$M$10,2)) -> 17.8 | N34: 46 | O34: 49 | P34: 45 | Q34: =IF(COUNT($N34:$P34)=0,"",SUM($N34:$P34)) -> 140 | R34: =IF(ISERROR(IF($Q34="","",ROUND(($Q34/$Q$10)*$R$10,2))),"",IF($Q34="","",ROUND(($Q34/$Q$10)*$R$10,2))) -> 93.33 | S34: =IF($R34="","",ROUND($R34*$S$10,2)) -> 46.67 | T34: 35 | U34: 36 | V34: 32 | W34: =IF(COUNT($T34:$V34)=0,"",SUM($T34:$V34)) -> 103 | X34: =IF(ISERROR(IF($W34="","",ROUND(($W34/$W$10)*$X$10,2))),"",IF($W34="","",ROUND(($W34/$W$10)*$X$10,2))) -> 85.83 | Y34: =IF($X34="","",ROUND($X34*$Y$10,2)) -> 25.75 | Z34: =IF(ISERROR(IF($V34="","",ROUND(SUM($M34,$S34,$Y34),2))),"",IF($V34="","",ROUND(SUM($M34,$S34,$Y34),2))) -> 90.22 | AA34: =IF(ISERROR(IF($V34="","",VLOOKUP(Z34,NewTransmu,4,TRUE))),"",IF($V34="","",VLOOKUP(Z34,NewTransmu,4,TRUE))) -> 92 | AB34: =IF(ISERROR(IF(AA34="","",VLOOKUP(AA34,DESCRIPTORS,4,TRUE))),"",IF(AA34="","",VLOOKUP(AA34,DESCRIPTORS,4,TRUE))) -> Advancing | AV34: =(T34/$T$10)*100 -> 87.5 | AW34: =(U34/$U$10)*100 -> 90 | AX34: =(V34/$V$10)*100 -> 80
A35: 24 | B35: =INPUT!B35 -> Pascual, Martin | F35: 17 | G35: 17 | H35: 17 | I35: 16 | J35: 17 | K35: =IF(COUNT($F35:$J35)=0,"",SUM($F35:$J35)) -> 84 | L35: =IF(ISERROR(IF($K35="","",ROUND(($K35/$K$10)*$L$10,2))),"",IF($K35="","",ROUND(($K35/$K$10)*$L$10,2))) -> 84 | M35: =IF($L35="","",ROUND($L35*$M$10,2)) -> 16.8 | N35: 40 | O35: 43 | P35: 45 | Q35: =IF(COUNT($N35:$P35)=0,"",SUM($N35:$P35)) -> 128 | R35: =IF(ISERROR(IF($Q35="","",ROUND(($Q35/$Q$10)*$R$10,2))),"",IF($Q35="","",ROUND(($Q35/$Q$10)*$R$10,2))) -> 85.33 | S35: =IF($R35="","",ROUND($R35*$S$10,2)) -> 42.67 | T35: 34 | U35: 34 | V35: 34 | W35: =IF(COUNT($T35:$V35)=0,"",SUM($T35:$V35)) -> 102 | X35: =IF(ISERROR(IF($W35="","",ROUND(($W35/$W$10)*$X$10,2))),"",IF($W35="","",ROUND(($W35/$W$10)*$X$10,2))) -> 85 | Y35: =IF($X35="","",ROUND($X35*$Y$10,2)) -> 25.5 | Z35: =IF(ISERROR(IF($V35="","",ROUND(SUM($M35,$S35,$Y35),2))),"",IF($V35="","",ROUND(SUM($M35,$S35,$Y35),2))) -> 84.97 | AA35: =IF(ISERROR(IF($V35="","",VLOOKUP(Z35,NewTransmu,4,TRUE))),"",IF($V35="","",VLOOKUP(Z35,NewTransmu,4,TRUE))) -> 86 | AB35: =IF(ISERROR(IF(AA35="","",VLOOKUP(AA35,DESCRIPTORS,4,TRUE))),"",IF(AA35="","",VLOOKUP(AA35,DESCRIPTORS,4,TRUE))) -> Benchmarking | AV35: =(T35/$T$10)*100 -> 85 | AW35: =(U35/$U$10)*100 -> 85 | AX35: =(V35/$V$10)*100 -> 85
A36: 25 | B36: =INPUT!B36 -> Quizon, Matthew | F36: 15 | G36: 17 | H36: 15 | I36: 16 | J36: 17 | K36: =IF(COUNT($F36:$J36)=0,"",SUM($F36:$J36)) -> 80 | L36: =IF(ISERROR(IF($K36="","",ROUND(($K36/$K$10)*$L$10,2))),"",IF($K36="","",ROUND(($K36/$K$10)*$L$10,2))) -> 80 | M36: =IF($L36="","",ROUND($L36*$M$10,2)) -> 16 | N36: 44 | O36: 44 | P36: 43 | Q36: =IF(COUNT($N36:$P36)=0,"",SUM($N36:$P36)) -> 131 | R36: =IF(ISERROR(IF($Q36="","",ROUND(($Q36/$Q$10)*$R$10,2))),"",IF($Q36="","",ROUND(($Q36/$Q$10)*$R$10,2))) -> 87.33 | S36: =IF($R36="","",ROUND($R36*$S$10,2)) -> 43.67 | T36: 30 | U36: 30 | V36: 32 | W36: =IF(COUNT($T36:$V36)=0,"",SUM($T36:$V36)) -> 92 | X36: =IF(ISERROR(IF($W36="","",ROUND(($W36/$W$10)*$X$10,2))),"",IF($W36="","",ROUND(($W36/$W$10)*$X$10,2))) -> 76.67 | Y36: =IF($X36="","",ROUND($X36*$Y$10,2)) -> 23 | Z36: =IF(ISERROR(IF($V36="","",ROUND(SUM($M36,$S36,$Y36),2))),"",IF($V36="","",ROUND(SUM($M36,$S36,$Y36),2))) -> 82.67 | AA36: =IF(ISERROR(IF($V36="","",VLOOKUP(Z36,NewTransmu,4,TRUE))),"",IF($V36="","",VLOOKUP(Z36,NewTransmu,4,TRUE))) -> 84 | AB36: =IF(ISERROR(IF(AA36="","",VLOOKUP(AA36,DESCRIPTORS,4,TRUE))),"",IF(AA36="","",VLOOKUP(AA36,DESCRIPTORS,4,TRUE))) -> Benchmarking | AV36: =(T36/$T$10)*100 -> 75 | AW36: =(U36/$U$10)*100 -> 75 | AX36: =(V36/$V$10)*100 -> 80
A37: 26 | B37: =INPUT!B37 -> Ramos, Miguel | F37: 17 | G37: 18 | H37: 17 | I37: 16 | J37: 17 | K37: =IF(COUNT($F37:$J37)=0,"",SUM($F37:$J37)) -> 85 | L37: =IF(ISERROR(IF($K37="","",ROUND(($K37/$K$10)*$L$10,2))),"",IF($K37="","",ROUND(($K37/$K$10)*$L$10,2))) -> 85 | M37: =IF($L37="","",ROUND($L37*$M$10,2)) -> 17 | N37: 40 | O37: 43 | P37: 43 | Q37: =IF(COUNT($N37:$P37)=0,"",SUM($N37:$P37)) -> 126 | R37: =IF(ISERROR(IF($Q37="","",ROUND(($Q37/$Q$10)*$R$10,2))),"",IF($Q37="","",ROUND(($Q37/$Q$10)*$R$10,2))) -> 84 | S37: =IF($R37="","",ROUND($R37*$S$10,2)) -> 42 | T37: 31 | U37: 30 | V37: 31 | W37: =IF(COUNT($T37:$V37)=0,"",SUM($T37:$V37)) -> 92 | X37: =IF(ISERROR(IF($W37="","",ROUND(($W37/$W$10)*$X$10,2))),"",IF($W37="","",ROUND(($W37/$W$10)*$X$10,2))) -> 76.67 | Y37: =IF($X37="","",ROUND($X37*$Y$10,2)) -> 23 | Z37: =IF(ISERROR(IF($V37="","",ROUND(SUM($M37,$S37,$Y37),2))),"",IF($V37="","",ROUND(SUM($M37,$S37,$Y37),2))) -> 82 | AA37: =IF(ISERROR(IF($V37="","",VLOOKUP(Z37,NewTransmu,4,TRUE))),"",IF($V37="","",VLOOKUP(Z37,NewTransmu,4,TRUE))) -> 84 | AB37: =IF(ISERROR(IF(AA37="","",VLOOKUP(AA37,DESCRIPTORS,4,TRUE))),"",IF(AA37="","",VLOOKUP(AA37,DESCRIPTORS,4,TRUE))) -> Benchmarking | AV37: =(T37/$T$10)*100 -> 77.5 | AW37: =(U37/$U$10)*100 -> 75 | AX37: =(V37/$V$10)*100 -> 77.5
A38: 27 | B38: =INPUT!B38 -> Reyes, Nathan | F38: 18 | G38: 18 | H38: 19 | I38: 17 | J38: 19 | K38: =IF(COUNT($F38:$J38)=0,"",SUM($F38:$J38)) -> 91 | L38: =IF(ISERROR(IF($K38="","",ROUND(($K38/$K$10)*$L$10,2))),"",IF($K38="","",ROUND(($K38/$K$10)*$L$10,2))) -> 91 | M38: =IF($L38="","",ROUND($L38*$M$10,2)) -> 18.2 | N38: 44 | O38: 45 | P38: 45 | Q38: =IF(COUNT($N38:$P38)=0,"",SUM($N38:$P38)) -> 134 | R38: =IF(ISERROR(IF($Q38="","",ROUND(($Q38/$Q$10)*$R$10,2))),"",IF($Q38="","",ROUND(($Q38/$Q$10)*$R$10,2))) -> 89.33 | S38: =IF($R38="","",ROUND($R38*$S$10,2)) -> 44.67 | T38: 32 | U38: 33 | V38: 32 | W38: =IF(COUNT($T38:$V38)=0,"",SUM($T38:$V38)) -> 97 | X38: =IF(ISERROR(IF($W38="","",ROUND(($W38/$W$10)*$X$10,2))),"",IF($W38="","",ROUND(($W38/$W$10)*$X$10,2))) -> 80.83 | Y38: =IF($X38="","",ROUND($X38*$Y$10,2)) -> 24.25 | Z38: =IF(ISERROR(IF($V38="","",ROUND(SUM($M38,$S38,$Y38),2))),"",IF($V38="","",ROUND(SUM($M38,$S38,$Y38),2))) -> 87.12 | AA38: =IF(ISERROR(IF($V38="","",VLOOKUP(Z38,NewTransmu,4,TRUE))),"",IF($V38="","",VLOOKUP(Z38,NewTransmu,4,TRUE))) -> 89 | AB38: =IF(ISERROR(IF(AA38="","",VLOOKUP(AA38,DESCRIPTORS,4,TRUE))),"",IF(AA38="","",VLOOKUP(AA38,DESCRIPTORS,4,TRUE))) -> Benchmarking | AV38: =(T38/$T$10)*100 -> 80 | AW38: =(U38/$U$10)*100 -> 82.5 | AX38: =(V38/$V$10)*100 -> 80
A39: 28 | B39: =INPUT!B39 -> Rivera, Noah | F39: 8 | G39: 9 | H39: 10 | I39: 8 | J39: 10 | K39: =IF(COUNT($F39:$J39)=0,"",SUM($F39:$J39)) -> 45 | L39: =IF(ISERROR(IF($K39="","",ROUND(($K39/$K$10)*$L$10,2))),"",IF($K39="","",ROUND(($K39/$K$10)*$L$10,2))) -> 45 | M39: =IF($L39="","",ROUND($L39*$M$10,2)) -> 9 | N39: 26 | O39: 26 | P39: 25 | Q39: =IF(COUNT($N39:$P39)=0,"",SUM($N39:$P39)) -> 77 | R39: =IF(ISERROR(IF($Q39="","",ROUND(($Q39/$Q$10)*$R$10,2))),"",IF($Q39="","",ROUND(($Q39/$Q$10)*$R$10,2))) -> 51.33 | S39: =IF($R39="","",ROUND($R39*$S$10,2)) -> 25.67 | T39: 14 | U39: 16 | V39: 17 | W39: =IF(COUNT($T39:$V39)=0,"",SUM($T39:$V39)) -> 47 | X39: =IF(ISERROR(IF($W39="","",ROUND(($W39/$W$10)*$X$10,2))),"",IF($W39="","",ROUND(($W39/$W$10)*$X$10,2))) -> 39.17 | Y39: =IF($X39="","",ROUND($X39*$Y$10,2)) -> 11.75 | Z39: =IF(ISERROR(IF($V39="","",ROUND(SUM($M39,$S39,$Y39),2))),"",IF($V39="","",ROUND(SUM($M39,$S39,$Y39),2))) -> 46.42 | AA39: =IF(ISERROR(IF($V39="","",VLOOKUP(Z39,NewTransmu,4,TRUE))),"",IF($V39="","",VLOOKUP(Z39,NewTransmu,4,TRUE))) -> 63 | AB39: =IF(ISERROR(IF(AA39="","",VLOOKUP(AA39,DESCRIPTORS,4,TRUE))),"",IF(AA39="","",VLOOKUP(AA39,DESCRIPTORS,4,TRUE))) -> Emerging | AV39: =(T39/$T$10)*100 -> 35 | AW39: =(U39/$U$10)*100 -> 40 | AX39: =(V39/$V$10)*100 -> 42.5
A40: 29 | B40: =INPUT!B40 -> Rosales, Oliver | F40: 15 | G40: 16 | H40: 16 | I40: 18 | J40: 15 | K40: =IF(COUNT($F40:$J40)=0,"",SUM($F40:$J40)) -> 80 | L40: =IF(ISERROR(IF($K40="","",ROUND(($K40/$K$10)*$L$10,2))),"",IF($K40="","",ROUND(($K40/$K$10)*$L$10,2))) -> 80 | M40: =IF($L40="","",ROUND($L40*$M$10,2)) -> 16 | N40: 43 | O40: 46 | P40: 46 | Q40: =IF(COUNT($N40:$P40)=0,"",SUM($N40:$P40)) -> 135 | R40: =IF(ISERROR(IF($Q40="","",ROUND(($Q40/$Q$10)*$R$10,2))),"",IF($Q40="","",ROUND(($Q40/$Q$10)*$R$10,2))) -> 90 | S40: =IF($R40="","",ROUND($R40*$S$10,2)) -> 45 | T40: 29 | U40: 30 | V40: 30 | W40: =IF(COUNT($T40:$V40)=0,"",SUM($T40:$V40)) -> 89 | X40: =IF(ISERROR(IF($W40="","",ROUND(($W40/$W$10)*$X$10,2))),"",IF($W40="","",ROUND(($W40/$W$10)*$X$10,2))) -> 74.17 | Y40: =IF($X40="","",ROUND($X40*$Y$10,2)) -> 22.25 | Z40: =IF(ISERROR(IF($V40="","",ROUND(SUM($M40,$S40,$Y40),2))),"",IF($V40="","",ROUND(SUM($M40,$S40,$Y40),2))) -> 83.25 | AA40: =IF(ISERROR(IF($V40="","",VLOOKUP(Z40,NewTransmu,4,TRUE))),"",IF($V40="","",VLOOKUP(Z40,NewTransmu,4,TRUE))) -> 85 | AB40: =IF(ISERROR(IF(AA40="","",VLOOKUP(AA40,DESCRIPTORS,4,TRUE))),"",IF(AA40="","",VLOOKUP(AA40,DESCRIPTORS,4,TRUE))) -> Benchmarking | AV40: =(T40/$T$10)*100 -> 72.5 | AW40: =(U40/$U$10)*100 -> 75 | AX40: =(V40/$V$10)*100 -> 75
A41: 30 | B41: =INPUT!B41 -> Salazar, Paolo | F41: 17 | G41: 18 | H41: 18 | I41: 16 | J41: 17 | K41: =IF(COUNT($F41:$J41)=0,"",SUM($F41:$J41)) -> 86 | L41: =IF(ISERROR(IF($K41="","",ROUND(($K41/$K$10)*$L$10,2))),"",IF($K41="","",ROUND(($K41/$K$10)*$L$10,2))) -> 86 | M41: =IF($L41="","",ROUND($L41*$M$10,2)) -> 17.2 | N41: 42 | O41: 42 | P41: 46 | Q41: =IF(COUNT($N41:$P41)=0,"",SUM($N41:$P41)) -> 130 | R41: =IF(ISERROR(IF($Q41="","",ROUND(($Q41/$Q$10)*$R$10,2))),"",IF($Q41="","",ROUND(($Q41/$Q$10)*$R$10,2))) -> 86.67 | S41: =IF($R41="","",ROUND($R41*$S$10,2)) -> 43.34 | T41: 33 | U41: 30 | V41: 34 | W41: =IF(COUNT($T41:$V41)=0,"",SUM($T41:$V41)) -> 97 | X41: =IF(ISERROR(IF($W41="","",ROUND(($W41/$W$10)*$X$10,2))),"",IF($W41="","",ROUND(($W41/$W$10)*$X$10,2))) -> 80.83 | Y41: =IF($X41="","",ROUND($X41*$Y$10,2)) -> 24.25 | Z41: =IF(ISERROR(IF($V41="","",ROUND(SUM($M41,$S41,$Y41),2))),"",IF($V41="","",ROUND(SUM($M41,$S41,$Y41),2))) -> 84.79 | AA41: =IF(ISERROR(IF($V41="","",VLOOKUP(Z41,NewTransmu,4,TRUE))),"",IF($V41="","",VLOOKUP(Z41,NewTransmu,4,TRUE))) -> 86 | AB41: =IF(ISERROR(IF(AA41="","",VLOOKUP(AA41,DESCRIPTORS,4,TRUE))),"",IF(AA41="","",VLOOKUP(AA41,DESCRIPTORS,4,TRUE))) -> Benchmarking | AV41: =(T41/$T$10)*100 -> 82.5 | AW41: =(U41/$U$10)*100 -> 75 | AX41: =(V41/$V$10)*100 -> 85
A42: 31 | B42: =INPUT!B42 -> Santiago, Patrick | F42: 18 | G42: 18 | H42: 19 | I42: 20 | J42: 20 | K42: =IF(COUNT($F42:$J42)=0,"",SUM($F42:$J42)) -> 95 | L42: =IF(ISERROR(IF($K42="","",ROUND(($K42/$K$10)*$L$10,2))),"",IF($K42="","",ROUND(($K42/$K$10)*$L$10,2))) -> 95 | M42: =IF($L42="","",ROUND($L42*$M$10,2)) -> 19 | N42: 47 | O42: 48 | P42: 46 | Q42: =IF(COUNT($N42:$P42)=0,"",SUM($N42:$P42)) -> 141 | R42: =IF(ISERROR(IF($Q42="","",ROUND(($Q42/$Q$10)*$R$10,2))),"",IF($Q42="","",ROUND(($Q42/$Q$10)*$R$10,2))) -> 94 | S42: =IF($R42="","",ROUND($R42*$S$10,2)) -> 47 | T42: 36 | U42: 37 | V42: 34 | W42: =IF(COUNT($T42:$V42)=0,"",SUM($T42:$V42)) -> 107 | X42: =IF(ISERROR(IF($W42="","",ROUND(($W42/$W$10)*$X$10,2))),"",IF($W42="","",ROUND(($W42/$W$10)*$X$10,2))) -> 89.17 | Y42: =IF($X42="","",ROUND($X42*$Y$10,2)) -> 26.75 | Z42: =IF(ISERROR(IF($V42="","",ROUND(SUM($M42,$S42,$Y42),2))),"",IF($V42="","",ROUND(SUM($M42,$S42,$Y42),2))) -> 92.75 | AA42: =IF(ISERROR(IF($V42="","",VLOOKUP(Z42,NewTransmu,4,TRUE))),"",IF($V42="","",VLOOKUP(Z42,NewTransmu,4,TRUE))) -> 94 | AB42: =IF(ISERROR(IF(AA42="","",VLOOKUP(AA42,DESCRIPTORS,4,TRUE))),"",IF(AA42="","",VLOOKUP(AA42,DESCRIPTORS,4,TRUE))) -> Advancing | AV42: =(T42/$T$10)*100 -> 90 | AW42: =(U42/$U$10)*100 -> 92.5 | AX42: =(V42/$V$10)*100 -> 85
A43: 32 | B43: =INPUT!B43 -> Santos, Rafael | F43: 18 | G43: 19 | H43: 19 | I43: 19 | J43: 18 | K43: =IF(COUNT($F43:$J43)=0,"",SUM($F43:$J43)) -> 93 | L43: =IF(ISERROR(IF($K43="","",ROUND(($K43/$K$10)*$L$10,2))),"",IF($K43="","",ROUND(($K43/$K$10)*$L$10,2))) -> 93 | M43: =IF($L43="","",ROUND($L43*$M$10,2)) -> 18.6 | N43: 49 | O43: 50 | P43: 50 | Q43: =IF(COUNT($N43:$P43)=0,"",SUM($N43:$P43)) -> 149 | R43: =IF(ISERROR(IF($Q43="","",ROUND(($Q43/$Q$10)*$R$10,2))),"",IF($Q43="","",ROUND(($Q43/$Q$10)*$R$10,2))) -> 99.33 | S43: =IF($R43="","",ROUND($R43*$S$10,2)) -> 49.67 | T43: 39 | U43: 35 | V43: 36 | W43: =IF(COUNT($T43:$V43)=0,"",SUM($T43:$V43)) -> 110 | X43: =IF(ISERROR(IF($W43="","",ROUND(($W43/$W$10)*$X$10,2))),"",IF($W43="","",ROUND(($W43/$W$10)*$X$10,2))) -> 91.67 | Y43: =IF($X43="","",ROUND($X43*$Y$10,2)) -> 27.5 | Z43: =IF(ISERROR(IF($V43="","",ROUND(SUM($M43,$S43,$Y43),2))),"",IF($V43="","",ROUND(SUM($M43,$S43,$Y43),2))) -> 95.77 | AA43: =IF(ISERROR(IF($V43="","",VLOOKUP(Z43,NewTransmu,4,TRUE))),"",IF($V43="","",VLOOKUP(Z43,NewTransmu,4,TRUE))) -> 97 | AB43: =IF(ISERROR(IF(AA43="","",VLOOKUP(AA43,DESCRIPTORS,4,TRUE))),"",IF(AA43="","",VLOOKUP(AA43,DESCRIPTORS,4,TRUE))) -> Advancing | AV43: =(T43/$T$10)*100 -> 97.5 | AW43: =(U43/$U$10)*100 -> 87.5 | AX43: =(V43/$V$10)*100 -> 90
...

Sheet TERM2
A1: Class Record
B4: REGION | G4: =INPUT!G4 -> Region IV-A (CALABARZON) | I4: DIVISION | L4: =INPUT!L4 -> Schools Division of Quezon
B5: SCHOOL NAME | G5: =INPUT!G5 -> Atimonan Central School Annex | Q5: SCHOOL ID | S5: =INPUT!S5 -> 108511 | V5: SCHOOL YEAR | Z5: =INPUT!Y5 -> 2025-2026
A7: TERM 2 | F7: GRADE & SECTION: | J7: =INPUT!J7 -> Grade 6 - Rizal | N7: TEACHER: | Q7: =INPUT!Q7 -> Jose Miguel Reyes | X7: SUBJECT: | Z7: =INPUT!Y7 -> Araling Panlipunan
B8: LEARNERS' NAMES | F8: WRITTEN / ORAL WORKS (20%) | N8: PRODUCT / PERFORMANCE TASKS (50%) | T8: SUMMATIVE TESTS AND TERM EXAMINATIONS (30%) | Z8: Initial Grade | AA8: Term Grade | AB8: Descriptior
F9: 1 | G9: 2 | H9: 3 | I9: 4 | J9: 5 | K9: Total | L9: PS | M9: WS | N9: 1 | O9: 2 | P9: 3 | Q9: Total | R9: PS | S9: WS | T9: ST1 | U9: ST2 | V9: TE | W9: Total | X9: PS | Y9: WS
B10: HIGHEST POSSIBLE SCORE | F10: 20 | G10: 20 | H10: 20 | I10: 20 | J10: 20 | K10: =IF(COUNT($F10:$J10)=0,"",SUM($F10:$J10)) -> 100 | L10: 100 | M10: 0.2 | N10: 50 | O10: 50 | P10: 50 | Q10: =IF(COUNT($N10:$P10)=0,"",SUM($N10:$P10)) -> 150 | R10: 100 | S10: 0.5 | T10: 40 | U10: 40 | V10: 40 | W10: {=IF(COUNT($T10:$V10=0),"",SUM($T10:$V10))} -> 120 | X10: 100 | Y10: 0.3
B11: MALE | AD11: TEST/EXAM RESULT ANALYSIS | AV11: ST1 | AW11: ST2 | AX11: TE
A12: 1 | B12: =INPUT!B12 -> Aguilar, Adrian | F12: 18 | G12: 17 | H12: 19 | I12: 17 | J12: 19 | K12: =IF(COUNT($F12:$J12)=0,"",SUM($F12:$J12)) -> 90 | L12: =IF(ISERROR(IF($K12="","",ROUND(($K12/$K$10)*$L$10,2))),"",IF($K12="","",ROUND(($K12/$K$10)*$L$10,2))) -> 90 | M12: =IF($L12="","",ROUND($L12*$M$10,2)) -> 18 | N12: 49 | O12: 47 | P12: 46 | Q12: =IF(COUNT($N12:$P12)=0,"",SUM($N12:$P12)) -> 142 | R12: =IF(ISERROR(IF($Q12="","",ROUND(($Q12/$Q$10)*$R$10,2))),"",IF($Q12="","",ROUND(($Q12/$Q$10)*$R$10,2))) -> 94.67 | S12: =IF($R12="","",ROUND($R12*$S$10,2)) -> 47.34 | T12: 36 | U12: 33 | V12: 35 | W12: =IF(COUNT($T12:$V12)=0,"",SUM($T12:$V12)) -> 104 | X12: =IF(ISERROR(IF($W12="","",ROUND(($W12/$W$10)*$X$10,2))),"",IF($W12="","",ROUND(($W12/$W$10)*$X$10,2))) -> 86.67 | Y12: =IF($X12="","",ROUND($X12*$Y$10,2)) -> 26 | Z12: =IF(ISERROR(IF($W12="","",ROUND(SUM($M12,$S12,$Y12),2))),"",IF($W12="","",ROUND(SUM($M12,$S12,$Y12),2))) -> 91.34 | AA12: =IF(ISERROR(IF($W12="","",VLOOKUP(Z12,NewTransmu,4,TRUE))),"",IF($W12="","",VLOOKUP(Z12,NewTransmu,4,TRUE))) -> 93 | AB12: =IF(ISERROR(IF(AA12="","",VLOOKUP(AA12,DESCRIPTORS,4,TRUE))),"",IF(AA12="","",VLOOKUP(AA12,DESCRIPTORS,4,TRUE))) -> Advancing | AV12: =(T12/$T$10)*100 -> 90 | AW12: =(U12/$U$10)*100 -> 82.5 | AX12: =(V12/$V$10)*100 -> 87.5
A13: 2 | B13: =INPUT!B13 -> Alcantara, Angelo | F13: 20 | G13: 20 | H13: 20 | I13: 20 | J13: 20 | K13: =IF(COUNT($F13:$J13)=0,"",SUM($F13:$J13)) -> 100 | L13: =IF(ISERROR(IF($K13="","",ROUND(($K13/$K$10)*$L$10,2))),"",IF($K13="","",ROUND(($K13/$K$10)*$L$10,2))) -> 100 | M13: =IF($L13="","",ROUND($L13*$M$10,2)) -> 20 | N13: 50 | O13: 50 | P13: 50 | Q13: =IF(COUNT($N13:$P13)=0,"",SUM($N13:$P13)) -> 150 | R13: =IF(ISERROR(IF($Q13="","",ROUND(($Q13/$Q$10)*$R$10,2))),"",IF($Q13="","",ROUND(($Q13/$Q$10)*$R$10,2))) -> 100 | S13: =IF($R13="","",ROUND($R13*$S$10,2)) -> 50 | T13: 36 | U13: 37 | V13: 35 | W13: =IF(COUNT($T13:$V13)=0,"",SUM($T13:$V13)) -> 108 | X13: =IF(ISERROR(IF($W13="","",ROUND(($W13/$W$10)*$X$10,2))),"",IF($W13="","",ROUND(($W13/$W$10)*$X$10,2))) -> 90 | Y13: =IF($X13="","",ROUND($X13*$Y$10,2)) -> 27 | Z13: =IF(ISERROR(IF($V13="","",ROUND(SUM($M13,$S13,$Y13),2))),"",IF($V13="","",ROUND(SUM($M13,$S13,$Y13),2))) -> 97 | AA13: =IF(ISERROR(IF($V13="","",VLOOKUP(Z13,NewTransmu,4,TRUE))),"",IF($V13="","",VLOOKUP(Z13,NewTransmu,4,TRUE))) -> 98 | AB13: =IF(ISERROR(IF(AA13="","",VLOOKUP(AA13,DESCRIPTORS,4,TRUE))),"",IF(AA13="","",VLOOKUP(AA13,DESCRIPTORS,4,TRUE))) -> Advancing | AE13: ST1 | AF13: ST2 | AG13: TE | AV13: =(T13/$T$10)*100 -> 90 | AW13: =(U13/$U$10)*100 -> 92.5 | AX13: =(V13/$V$10)*100 -> 87.5
A14: 3 | B14: =INPUT!B14 -> Andrada, Anton | F14: 17 | G14: 16 | H14: 18 | I14: 16 | J14: 17 | K14: =IF(COUNT($F14:$J14)=0,"",SUM($F14:$J14)) -> 84 | L14: =IF(ISERROR(IF($K14="","",ROUND(($K14/$K$10)*$L$10,2))),"",IF($K14="","",ROUND(($K14/$K$10)*$L$10,2))) -> 84 | M14: =IF($L14="","",ROUND($L14*$M$10,2)) -> 16.8 | N14: 42 | O14: 44 | P14: 45 | Q14: =IF(COUNT($N14:$P14)=0,"",SUM($N14:$P14)) -> 131 | R14: =IF(ISERROR(IF($Q14="","",ROUND(($Q14/$Q$10)*$R$10,2))),"",IF($Q14="","",ROUND(($Q14/$Q$10)*$R$10,2))) -> 87.33 | S14: =IF($R14="","",ROUND($R14*$S$10,2)) -> 43.67 | T14: 31 | U14: 31 | V14: 32 | W14: =IF(COUNT($T14:$V14)=0,"",SUM($T14:$V14)) -> 94 | X14: =IF(ISERROR(IF($W14="","",ROUND(($W14/$W$10)*$X$10,2))),"",IF($W14="","",ROUND(($W14/$W$10)*$X$10,2))) -> 78.33 | Y14: =IF($X14="","",ROUND($X14*$Y$10,2)) -> 23.5 | Z14: =IF(ISERROR(IF($V14="","",ROUND(SUM($M14,$S14,$Y14),2))),"",IF($V14="","",ROUND(SUM($M14,$S14,$Y14),2))) -> 83.97 | AA14: =IF(ISERROR(IF($V14="","",VLOOKUP(Z14,NewTransmu,4,TRUE))),"",IF($V14="","",VLOOKUP(Z14,NewTransmu,4,TRUE))) -> 85 | AB14: =IF(ISERROR(IF(AA14="","",VLOOKUP(AA14,DESCRIPTORS,4,TRUE))),"",IF(AA14="","",VLOOKUP(AA14,DESCRIPTORS,4,TRUE))) -> Benchmarking | AD14: Number of Examinees: | AE14: =COUNTA(T12:T112) -> 100 | AF14: =COUNTA(U12:U112) -> 100 | AG14: =COUNTA(V12:V112) -> 100 | AV14: =(T14/$T$10)*100 -> 77.5 | AW14: =(U14/$U$10)*100 -> 77.5 | AX14: =(V14/$V$10)*100 -> 80
A15: 4 | B15: =INPUT!B15 -> Bautista, Bryan | F15: 14 | G15: 15 | H15: 16 | I15: 14 | J15: 15 | K15: =IF(COUNT($F15:$J15)=0,"",SUM($F15:$J15)) -> 74 | L15: =IF(ISERROR(IF($K15="","",ROUND(($K15/$K$10)*$L$10,2))),"",IF($K15="","",ROUND(($K15/$K$10)*$L$10,2))) -> 74 | M15: =IF($L15="","",ROUND($L15*$M$10,2)) -> 14.8 | N15: 38 | O15: 38 | P15: 43 | Q15: =IF(COUNT($N15:$P15)=0,"",SUM($N15:$P15)) -> 119 | R15: =IF(ISERROR(IF($Q15="","",ROUND(($Q15/$Q$10)*$R$10,2))),"",IF($Q15="","",ROUND(($Q15/$Q$10)*$R$10,2))) -> 79.33 | S15: =IF($R15="","",ROUND($R15*$S$10,2)) -> 39.67 | T15: 30 | U15: 29 | V15: 29 | W15: =IF(COUNT($T15:$V15)=0,"",SUM($T15:$V15)) -> 88 | X15: =IF(ISERROR(IF($W15="","",ROUND(($W15/$W$10)*$X$10,2))),"",IF($W15="","",ROUND(($W15/$W$10)*$X$10,2))) -> 73.33 | Y15: =IF($X15="","",ROUND($X15*$Y$10,2)) -> 22 | Z15: =IF(ISERROR(IF($V15="","",ROUND(SUM($M15,$S15,$Y15),2))),"",IF($V15="","",ROUND(SUM($M15,$S15,$Y15),2))) -> 76.47 | AA15: =IF(ISERROR(IF($V15="","",VLOOKUP(Z15,NewTransmu,4,TRUE))),"",IF($V15="","",VLOOKUP(Z15,NewTransmu,4,TRUE))) -> 78 | AB15: =IF(ISERROR(IF(AA15="","",VLOOKUP(AA15,DESCRIPTORS,4,TRUE))),"",IF(AA15="","",VLOOKUP(AA15,DESCRIPTORS,4,TRUE))) -> Connecting | AD15: Highest Possible Score: | AE15: =T10 -> 40 | AF15: =U10 -> 40 | AG15: =V10 -> 40 | AV15: =(T15/$T$10)*100 -> 75 | AW15: =(U15/$U$10)*100 -> 72.5 | AX15: =(V15/$V$10)*100 -> 72.5
A16: 5 | B16: =INPUT!B16 -> Bernardo, Caleb | F16: 19 | G16: 20 | H16: 19 | I16: 19 | J16: 20 | K16: =IF(COUNT($F16:$J16)=0,"",SUM($F16:$J16)) -> 97 | L16: =IF(ISERROR(IF($K16="","",ROUND(($K16/$K$10)*$L$10,2))),"",IF($K16="","",ROUND(($K16/$K$10)*$L$10,2))) -> 97 | M16: =IF($L16="","",ROUND($L16*$M$10,2)) -> 19.4 | N16: 50 | O16: 50 | P16: 50 | Q16: =IF(COUNT($N16:$P16)=0,"",SUM($N16:$P16)) -> 150 | R16: =IF(ISERROR(IF($Q16="","",ROUND(($Q16/$Q$10)*$R$10,2))),"",IF($Q16="","",ROUND(($Q16/$Q$10)*$R$10,2))) -> 100 | S16: =IF($R16="","",ROUND($R16*$S$10,2)) -> 50 | T16: 37 | U16: 40 | V16: 37 | W16: =IF(COUNT($T16:$V16)=0,"",SUM($T16:$V16)) -> 114 | X16: =IF(ISERROR(IF($W16="","",ROUND(($W16/$W$10)*$X$10,2))),"",IF($W16="","",ROUND(($W16/$W$10)*$X$10,2))) -> 95 | Y16: =IF($X16="","",ROUND($X16*$Y$10,2)) -> 28.5 | Z16: =IF(ISERROR(IF($V16="","",ROUND(SUM($M16,$S16,$Y16),2))),"",IF($V16="","",ROUND(SUM($M16,$S16,$Y16),2))) -> 97.9 | AA16: =IF(ISERROR(IF($V16="","",VLOOKUP(Z16,NewTransmu,4,TRUE))),"",IF($V16="","",VLOOKUP(Z16,NewTransmu,4,TRUE))) -> 99 | AB16: =IF(ISERROR(IF(AA16="","",VLOOKUP(AA16,DESCRIPTORS,4,TRUE))),"",IF(AA16="","",VLOOKUP(AA16,DESCRIPTORS,4,TRUE))) -> Advancing | AV16: =(T16/$T$10)*100 -> 92.5 | AW16: =(U16/$U$10)*100 -> 100 | AX16: =(V16/$V$10)*100 -> 92.5
A17: 6 | B17: =INPUT!B17 -> Castillo, Carlo | F17: 18 | G17: 18 | H17: 19 | I17: 19 | J17: 19 | K17: =IF(COUNT($F17:$J17)=0,"",SUM($F17:$J17)) -> 93 | L17: =IF(ISERROR(IF($K17="","",ROUND(($K17/$K$10)*$L$10,2))),"",IF($K17="","",ROUND(($K17/$K$10)*$L$10,2))) -> 93 | M17: =IF($L17="","",ROUND($L17*$M$10,2)) -> 18.6 | N17: 43 | O17: 45 | P17: 50 | Q17: =IF(COUNT($N17:$P17)=0,"",SUM($N17:$P17)) -> 138 | R17: =IF(ISERROR(IF($Q17="","",ROUND(($Q17/$Q$10)*$R$10,2))),"",IF($Q17="","",ROUND(($Q17/$Q$10)*$R$10,2))) -> 92 | S17: =IF($R17="","",ROUND($R17*$S$10,2)) -> 46 | T17: 36 | U17: 34 | V17: 34 | W17: =IF(COUNT($T17:$V17)=0,"",SUM($T17:$V17)) -> 104 | X17: =IF(ISERROR(IF($W17="","",ROUND(($W17/$W$10)*$X$10,2))),"",IF($W17="","",ROUND(($W17/$W$10)*$X$10,2))) -> 86.67 | Y17: =IF($X17="","",ROUND($X17*$Y$10,2)) -> 26 | Z17: =IF(ISERROR(IF($V17="","",ROUND(SUM($M17,$S17,$Y17),2))),"",IF($V17="","",ROUND(SUM($M17,$S17,$Y17),2))) -> 90.6 | AA17: =IF(ISERROR(IF($V17="","",VLOOKUP(Z17,NewTransmu,4,TRUE))),"",IF($V17="","",VLOOKUP(Z17,NewTransmu,4,TRUE))) -> 92 | AB17: =IF(ISERROR(IF(AA17="","",VLOOKUP(AA17,DESCRIPTORS,4,TRUE))),"",IF(AA17="","",VLOOKUP(AA17,DESCRIPTORS,4,TRUE))) -> Advancing | AD17: CRITERION-REFERENCED | AE17: ST1 | AF17: ST2 | AG17: TE | AV17: =(T17/$T$10)*100 -> 90 | AW17: =(U17/$U$10)*100 -> 85 | AX17: =(V17/$V$10)*100 -> 85
A18: 7 | B18: =INPUT!B18 -> Cruz, Christian | F18: 18 | G18: 17 | H18: 16 | I18: 16 | J18: 18 | K18: =IF(COUNT($F18:$J18)=0,"",SUM($F18:$J18)) -> 85 | L18: =IF(ISERROR(IF($K18="","",ROUND(($K18/$K$10)*$L$10,2))),"",IF($K18="","",ROUND(($K18/$K$10)*$L$10,2))) -> 85 | M18: =IF($L18="","",ROUND($L18*$M$10,2)) -> 17 | N18: 44 | O18: 46 | P18: 43 | Q18: =IF(COUNT($N18:$P18)=0,"",SUM($N18:$P18)) -> 133 | R18: =IF(ISERROR(IF($Q18="","",ROUND(($Q18/$Q$10)*$R$10,2))),"",IF($Q18="","",ROUND(($Q18/$Q$10)*$R$10,2))) -> 88.67 | S18: =IF($R18="","",ROUND($R18*$S$10,2)) -> 44.34 | T18: 31 | U18: 31 | V18: 33 | W18: =IF(COUNT($T18:$V18)=0,"",SUM($T18:$V18)) -> 95 | X18: =IF(ISERROR(IF($W18="","",ROUND(($W18/$W$10)*$X$10,2))),"",IF($W18="","",ROUND(($W18/$W$10)*$X$10,2))) -> 79.17 | Y18: =IF($X18="","",ROUND($X18*$Y$10,2)) -> 23.75 | Z18: =IF(ISERROR(IF($V18="","",ROUND(SUM($M18,$S18,$Y18),2))),"",IF($V18="","",ROUND(SUM($M18,$S18,$Y18),2))) -> 85.09 | AA18: =IF(ISERROR(IF($V18="","",VLOOKUP(Z18,NewTransmu,4,TRUE))),"",IF($V18="","",VLOOKUP(Z18,NewTransmu,4,TRUE))) -> 87 | AB18: =IF(ISERROR(IF(AA18="","",VLOOKUP(AA18,DESCRIPTORS,4,TRUE))),"",IF(AA18="","",VLOOKUP(AA18,DESCRIPTORS,4,TRUE))) -> Benchmarking | AD18: Got 75% & above | AE18: =COUNTIF(AV12:AV112,">=75") -> 76 | AF18: =COUNTIF(AW12:AW112,">=75") -> 77 | AG18: =COUNTIF(AX12:AX112,">=75") -> 78 | AV18: =(T18/$T$10)*100 -> 77.5 | AW18: =(U18/$U$10)*100 -> 77.5 | AX18: =(V18/$V$10)*100 -> 82.5
A19: 8 | B19: =INPUT!B19 -> Dela Cruz, Daniel | F19: 19 | G19: 20 | H19: 20 | I19: 19 | J19: 20 | K19: =IF(COUNT($F19:$J19)=0,"",SUM($F19:$J19)) -> 98 | L19: =IF(ISERROR(IF($K19="","",ROUND(($K19/$K$10)*$L$10,2))),"",IF($K19="","",ROUND(($K19/$K$10)*$L$10,2))) -> 98 | M19: =IF($L19="","",ROUND($L19*$M$10,2)) -> 19.6 | N19: 49 | O19: 50 | P19: 50 | Q19: =IF(COUNT($N19:$P19)=0,"",SUM($N19:$P19)) -> 149 | R19: =IF(ISERROR(IF($Q19="","",ROUND(($Q19/$Q$10)*$R$10,2))),"",IF($Q19="","",ROUND(($Q19/$Q$10)*$R$10,2))) -> 99.33 | S19: =IF($R19="","",ROUND($R19*$S$10,2)) -> 49.67 | T19: 37 | U19: 40 | V19: 36 | W19: =IF(COUNT($T19:$V19)=0,"",SUM($T19:$V19)) -> 113 | X19: =IF(ISERROR(IF($W19="","",ROUND(($W19/$W$10)*$X$10,2))),"",IF($W19="","",ROUND(($W19/$W$10)*$X$10,2))) -> 94.17 | Y19: =IF($X19="","",ROUND($X19*$Y$10,2)) -> 28.25 | Z19: =IF(ISERROR(IF($V19="","",ROUND(SUM($M19,$S19,$Y19),2))),"",IF($V19="","",ROUND(SUM($M19,$S19,$Y19),2))) -> 97.52 | AA19: =IF(ISERROR(IF($V19="","",VLOOKUP(Z19,NewTransmu,4,TRUE))),"",IF($V19="","",VLOOKUP(Z19,NewTransmu,4,TRUE))) -> 99 | AB19: =IF(ISERROR(IF(AA19="","",VLOOKUP(AA19,DESCRIPTORS,4,TRUE))),"",IF(AA19="","",VLOOKUP(AA19,DESCRIPTORS,4,TRUE))) -> Advancing | AD19: Percentage | AE19: =IFERROR(AE18/AE14,"") -> 0.76 | AF19: =IFERROR(AF18/AF14,"") -> 0.77 | AG19: =IFERROR(AG18/AG14,"") -> 0.78 | AV19: =(T19/$T$10)*100 -> 92.5 | AW19: =(U19/$U$10)*100 -> 100 | AX19: =(V19/$V$10)*100 -> 90
